2020-11-06 11:39:01,362 [DEBUG] {/usr/lib/python3.6/asyncio/selector_events.py:54} : Using selector: EpollSelector
2020-11-06 11:39:01,593 [INFO] {/home/rohit/Desktop/CRUD/env/lib/python3.6/site-packages/django/utils/autoreload.py:612} : Watching for file changes with StatReloader
2020-11-06 11:39:10,681 [INFO] {/home/rohit/Desktop/CRUD/env/lib/python3.6/site-packages/django/utils/autoreload.py:236} : /home/rohit/Desktop/CRUD/POLITICS/district/views.py changed, reloading.
2020-11-06 11:39:11,398 [DEBUG] {/usr/lib/python3.6/asyncio/selector_events.py:54} : Using selector: EpollSelector
2020-11-06 11:39:11,667 [INFO] {/home/rohit/Desktop/CRUD/env/lib/python3.6/site-packages/django/utils/autoreload.py:612} : Watching for file changes with StatReloader
2020-11-06 11:39:21,016 [INFO] {/home/rohit/Desktop/CRUD/env/lib/python3.6/site-packages/django/utils/autoreload.py:236} : /home/rohit/Desktop/CRUD/POLITICS/district/views.py changed, reloading.
2020-11-06 11:39:21,754 [DEBUG] {/usr/lib/python3.6/asyncio/selector_events.py:54} : Using selector: EpollSelector
2020-11-06 11:39:22,019 [INFO] {/home/rohit/Desktop/CRUD/env/lib/python3.6/site-packages/django/utils/autoreload.py:612} : Watching for file changes with StatReloader
2020-11-06 11:39:22,973 [DEBUG] {/home/rohit/Desktop/CRUD/POLITICS/district/views.py:359} : 2121212211
2020-11-06 11:39:50,742 [INFO] {/home/rohit/Desktop/CRUD/env/lib/python3.6/site-packages/django/utils/autoreload.py:236} : /home/rohit/Desktop/CRUD/POLITICS/config/settings.py changed, reloading.
2020-11-06 11:40:39,321 [DEBUG] {/usr/lib/python3.6/asyncio/selector_events.py:54} : Using selector: EpollSelector
2020-11-06 11:40:39,561 [INFO] {/home/rohit/Desktop/CRUD/env/lib/python3.6/site-packages/django/utils/autoreload.py:612} : Watching for file changes with StatReloader
2020-11-06 11:40:43,525 [INFO] {/home/rohit/Desktop/CRUD/env/lib/python3.6/site-packages/django/utils/autoreload.py:236} : /home/rohit/Desktop/CRUD/POLITICS/config/settings.py changed, reloading.
2020-11-06 11:40:44,043 [DEBUG] {/usr/lib/python3.6/asyncio/selector_events.py:54} : Using selector: EpollSelector
2020-11-06 11:40:44,275 [INFO] {/home/rohit/Desktop/CRUD/env/lib/python3.6/site-packages/django/utils/autoreload.py:612} : Watching for file changes with StatReloader
2020-11-06 11:40:45,631 [DEBUG] {/home/rohit/Desktop/CRUD/POLITICS/district/views.py:359} : 22222222222222222222
2020-11-06 11:41:07,586 [INFO] {/home/rohit/Desktop/CRUD/env/lib/python3.6/site-packages/django/utils/autoreload.py:236} : /home/rohit/Desktop/CRUD/POLITICS/config/settings.py changed, reloading.
2020-11-06 11:41:08,416 [INFO] {/home/rohit/Desktop/CRUD/env/lib/python3.6/site-packages/django/utils/autoreload.py:612} : Watching for file changes with StatReloader
2020-11-06 11:41:19,536 [INFO] {/home/rohit/Desktop/CRUD/env/lib/python3.6/site-packages/django/utils/autoreload.py:236} : /home/rohit/Desktop/CRUD/POLITICS/district/views.py changed, reloading.
2020-11-06 11:41:20,531 [INFO] {/home/rohit/Desktop/CRUD/env/lib/python3.6/site-packages/django/utils/autoreload.py:612} : Watching for file changes with StatReloader
2020-11-06 15:23:17,850 [INFO] {/home/rohit/Desktop/CRUD/env/lib/python3.6/site-packages/django/utils/autoreload.py:236} : /home/rohit/Desktop/CRUD/POLITICS/district/views.py changed, reloading.
2020-11-06 15:23:18,831 [INFO] {/home/rohit/Desktop/CRUD/env/lib/python3.6/site-packages/django/utils/autoreload.py:612} : Watching for file changes with StatReloader
2020-11-06 15:24:51,426 [INFO] {/home/rohit/Desktop/CRUD/env/lib/python3.6/site-packages/django/utils/autoreload.py:236} : /home/rohit/Desktop/CRUD/POLITICS/config/settings.py changed, reloading.
2020-11-06 15:24:52,012 [DEBUG] {/usr/lib/python3.6/asyncio/selector_events.py:54} : Using selector: EpollSelector
2020-11-06 15:24:52,256 [INFO] {/home/rohit/Desktop/CRUD/env/lib/python3.6/site-packages/django/utils/autoreload.py:612} : Watching for file changes with StatReloader
2020-11-06 15:24:55,463 [DEBUG] {/home/rohit/Desktop/CRUD/POLITICS/district/views.py:359} : debug log
2020-11-06 15:43:36,470 [INFO] {/home/rohit/Desktop/CRUD/env/lib/python3.6/site-packages/django/utils/autoreload.py:236} : /home/rohit/Desktop/CRUD/POLITICS/config/settings.py changed, reloading.
2020-11-06 15:43:48,461 [ERROR] {/home/rohit/Desktop/CRUD/POLITICS/district/views.py:359} : debug log
2020-11-06 15:44:22,181 [ERROR] {/home/rohit/Desktop/CRUD/POLITICS/district/views.py:359} : error logging
2020-11-06 15:44:44,297 [ERROR] {/home/rohit/Desktop/CRUD/POLITICS/district/views.py:359} : error logging
NoneType: None
2020-11-06 15:45:57,041 [ERROR] {/home/rohit/Desktop/CRUD/POLITICS/district/views.py:362} : error logging in except field!!!!
Traceback (most recent call last):
  File "/home/rohit/Desktop/CRUD/POLITICS/district/views.py", line 360, in test_model
    a = 1/0
ZeroDivisionError: division by zero
2020-11-06 15:47:08,288 [ERROR] {/home/rohit/Desktop/CRUD/POLITICS/district/views.py:362} : error logging in except field!!!!
2020-11-09 15:31:39,306 [ERROR] {/home/rohit/Desktop/CRUD/POLITICS/district/views.py:362} : error logging in except field!!!!
2020-11-12 14:55:48,936 [ERROR] {/home/rohit/Desktop/CRUD/env/lib/python3.6/site-packages/django/utils/log.py:230} : Internal Server Error: /district/View_Set/TVS
Traceback (most recent call last):
  File "/home/rohit/Desktop/CRUD/env/lib/python3.6/site-packages/django/core/handlers/exception.py", line 47, in inner
    response = get_response(request)
  File "/home/rohit/Desktop/CRUD/env/lib/python3.6/site-packages/django/utils/deprecation.py", line 113, in __call__
    response = self.process_request(request)
  File "/home/rohit/Desktop/CRUD/env/lib/python3.6/site-packages/django/middleware/common.py", line 54, in process_request
    path = self.get_full_path_with_slash(request)
  File "/home/rohit/Desktop/CRUD/env/lib/python3.6/site-packages/django/middleware/common.py", line 94, in get_full_path_with_slash
    'url': request.get_host() + new_path,
RuntimeError: You called this URL via POST, but the URL doesn't end in a slash and you have APPEND_SLASH set. Django can't redirect to the slash URL while maintaining POST data. Change your form to point to 127.0.0.1:8000/district/View_Set/TVS/ (note the trailing slash), or set APPEND_SLASH=False in your Django settings.
2020-11-12 14:57:18,663 [ERROR] {/home/rohit/Desktop/CRUD/env/lib/python3.6/site-packages/django/utils/log.py:230} : Internal Server Error: /district/View_Set/TVS/1
Traceback (most recent call last):
  File "/home/rohit/Desktop/CRUD/env/lib/python3.6/site-packages/django/core/handlers/exception.py", line 47, in inner
    response = get_response(request)
  File "/home/rohit/Desktop/CRUD/env/lib/python3.6/site-packages/django/utils/deprecation.py", line 113, in __call__
    response = self.process_request(request)
  File "/home/rohit/Desktop/CRUD/env/lib/python3.6/site-packages/django/middleware/common.py", line 54, in process_request
    path = self.get_full_path_with_slash(request)
  File "/home/rohit/Desktop/CRUD/env/lib/python3.6/site-packages/django/middleware/common.py", line 94, in get_full_path_with_slash
    'url': request.get_host() + new_path,
RuntimeError: You called this URL via PUT, but the URL doesn't end in a slash and you have APPEND_SLASH set. Django can't redirect to the slash URL while maintaining PUT data. Change your form to point to 127.0.0.1:8000/district/View_Set/TVS/1/ (note the trailing slash), or set APPEND_SLASH=False in your Django settings.
2020-11-13 16:12:37,510 [ERROR] {/home/rohit/Desktop/CRUD/env/lib/python3.6/site-packages/django/utils/log.py:230} : Internal Server Error: /district/View_Set/TVS
Traceback (most recent call last):
  File "/home/rohit/Desktop/CRUD/env/lib/python3.6/site-packages/django/core/handlers/exception.py", line 47, in inner
    response = get_response(request)
  File "/home/rohit/Desktop/CRUD/env/lib/python3.6/site-packages/django/utils/deprecation.py", line 113, in __call__
    response = self.process_request(request)
  File "/home/rohit/Desktop/CRUD/env/lib/python3.6/site-packages/django/middleware/common.py", line 54, in process_request
    path = self.get_full_path_with_slash(request)
  File "/home/rohit/Desktop/CRUD/env/lib/python3.6/site-packages/django/middleware/common.py", line 94, in get_full_path_with_slash
    'url': request.get_host() + new_path,
RuntimeError: You called this URL via POST, but the URL doesn't end in a slash and you have APPEND_SLASH set. Django can't redirect to the slash URL while maintaining POST data. Change your form to point to 127.0.0.1:8000/district/View_Set/TVS/ (note the trailing slash), or set APPEND_SLASH=False in your Django settings.
2020-11-13 16:13:31,422 [ERROR] {/home/rohit/Desktop/CRUD/env/lib/python3.6/site-packages/django/utils/log.py:230} : Internal Server Error: /district/View_Set/TVS/
Traceback (most recent call last):
  File "/home/rohit/Desktop/CRUD/env/lib/python3.6/site-packages/django/db/backends/mysql/base.py", line 73, in execute
    return self.cursor.execute(query, args)
  File "/home/rohit/Desktop/CRUD/env/lib/python3.6/site-packages/MySQLdb/cursors.py", line 209, in execute
    res = self._query(query)
  File "/home/rohit/Desktop/CRUD/env/lib/python3.6/site-packages/MySQLdb/cursors.py", line 315, in _query
    db.query(q)
  File "/home/rohit/Desktop/CRUD/env/lib/python3.6/site-packages/MySQLdb/connections.py", line 239, in query
    _mysql.connection.query(self, query)
MySQLdb._exceptions.OperationalError: (1048, "Column 'student_weight' cannot be null")

During handling of the above exception, another exception occurred:

Traceback (most recent call last):
  File "/home/rohit/Desktop/CRUD/env/lib/python3.6/site-packages/django/core/handlers/exception.py", line 47, in inner
    response = get_response(request)
  File "/home/rohit/Desktop/CRUD/env/lib/python3.6/site-packages/django/core/handlers/base.py", line 179, in _get_response
    response = wrapped_callback(request, *callback_args, **callback_kwargs)
  File "/home/rohit/Desktop/CRUD/env/lib/python3.6/site-packages/django/views/decorators/csrf.py", line 54, in wrapped_view
    return view_func(*args, **kwargs)
  File "/home/rohit/Desktop/CRUD/env/lib/python3.6/site-packages/rest_framework/viewsets.py", line 114, in view
    return self.dispatch(request, *args, **kwargs)
  File "/home/rohit/Desktop/CRUD/env/lib/python3.6/site-packages/rest_framework/views.py", line 505, in dispatch
    response = self.handle_exception(exc)
  File "/home/rohit/Desktop/CRUD/env/lib/python3.6/site-packages/rest_framework/views.py", line 465, in handle_exception
    self.raise_uncaught_exception(exc)
  File "/home/rohit/Desktop/CRUD/env/lib/python3.6/site-packages/rest_framework/views.py", line 476, in raise_uncaught_exception
    raise exc
  File "/home/rohit/Desktop/CRUD/env/lib/python3.6/site-packages/rest_framework/views.py", line 502, in dispatch
    response = handler(request, *args, **kwargs)
  File "/home/rohit/Desktop/CRUD/env/lib/python3.6/site-packages/rest_framework/mixins.py", line 19, in create
    self.perform_create(serializer)
  File "/home/rohit/Desktop/CRUD/env/lib/python3.6/site-packages/rest_framework/mixins.py", line 24, in perform_create
    serializer.save()
  File "/home/rohit/Desktop/CRUD/env/lib/python3.6/site-packages/rest_framework/serializers.py", line 212, in save
    self.instance = self.create(validated_data)
  File "/home/rohit/Desktop/CRUD/env/lib/python3.6/site-packages/rest_framework/serializers.py", line 948, in create
    instance = ModelClass._default_manager.create(**validated_data)
  File "/home/rohit/Desktop/CRUD/env/lib/python3.6/site-packages/django/db/models/manager.py", line 85, in manager_method
    return getattr(self.get_queryset(), name)(*args, **kwargs)
  File "/home/rohit/Desktop/CRUD/env/lib/python3.6/site-packages/django/db/models/query.py", line 447, in create
    obj.save(force_insert=True, using=self.db)
  File "/home/rohit/Desktop/CRUD/env/lib/python3.6/site-packages/django/db/models/base.py", line 754, in save
    force_update=force_update, update_fields=update_fields)
  File "/home/rohit/Desktop/CRUD/env/lib/python3.6/site-packages/django/db/models/base.py", line 792, in save_base
    force_update, using, update_fields,
  File "/home/rohit/Desktop/CRUD/env/lib/python3.6/site-packages/django/db/models/base.py", line 895, in _save_table
    results = self._do_insert(cls._base_manager, using, fields, returning_fields, raw)
  File "/home/rohit/Desktop/CRUD/env/lib/python3.6/site-packages/django/db/models/base.py", line 935, in _do_insert
    using=using, raw=raw,
  File "/home/rohit/Desktop/CRUD/env/lib/python3.6/site-packages/django/db/models/manager.py", line 85, in manager_method
    return getattr(self.get_queryset(), name)(*args, **kwargs)
  File "/home/rohit/Desktop/CRUD/env/lib/python3.6/site-packages/django/db/models/query.py", line 1249, in _insert
    return query.get_compiler(using=using).execute_sql(returning_fields)
  File "/home/rohit/Desktop/CRUD/env/lib/python3.6/site-packages/django/db/models/sql/compiler.py", line 1397, in execute_sql
    cursor.execute(sql, params)
  File "/home/rohit/Desktop/CRUD/env/lib/python3.6/site-packages/django/db/backends/utils.py", line 98, in execute
    return super().execute(sql, params)
  File "/home/rohit/Desktop/CRUD/env/lib/python3.6/site-packages/django/db/backends/utils.py", line 66, in execute
    return self._execute_with_wrappers(sql, params, many=False, executor=self._execute)
  File "/home/rohit/Desktop/CRUD/env/lib/python3.6/site-packages/django/db/backends/utils.py", line 75, in _execute_with_wrappers
    return executor(sql, params, many, context)
  File "/home/rohit/Desktop/CRUD/env/lib/python3.6/site-packages/django/db/backends/utils.py", line 84, in _execute
    return self.cursor.execute(sql, params)
  File "/home/rohit/Desktop/CRUD/env/lib/python3.6/site-packages/django/db/backends/mysql/base.py", line 78, in execute
    raise IntegrityError(*tuple(e.args))
django.db.utils.IntegrityError: (1048, "Column 'student_weight' cannot be null")
2020-11-13 16:16:40,115 [ERROR] {/home/rohit/Desktop/CRUD/env/lib/python3.6/site-packages/django/utils/log.py:230} : Internal Server Error: /district/View_Set/TVS/
Traceback (most recent call last):
  File "/home/rohit/Desktop/CRUD/env/lib/python3.6/site-packages/django/db/backends/mysql/base.py", line 73, in execute
    return self.cursor.execute(query, args)
  File "/home/rohit/Desktop/CRUD/env/lib/python3.6/site-packages/MySQLdb/cursors.py", line 209, in execute
    res = self._query(query)
  File "/home/rohit/Desktop/CRUD/env/lib/python3.6/site-packages/MySQLdb/cursors.py", line 315, in _query
    db.query(q)
  File "/home/rohit/Desktop/CRUD/env/lib/python3.6/site-packages/MySQLdb/connections.py", line 239, in query
    _mysql.connection.query(self, query)
MySQLdb._exceptions.OperationalError: (1048, "Column 'student_weight' cannot be null")

During handling of the above exception, another exception occurred:

Traceback (most recent call last):
  File "/home/rohit/Desktop/CRUD/env/lib/python3.6/site-packages/django/core/handlers/exception.py", line 47, in inner
    response = get_response(request)
  File "/home/rohit/Desktop/CRUD/env/lib/python3.6/site-packages/django/core/handlers/base.py", line 179, in _get_response
    response = wrapped_callback(request, *callback_args, **callback_kwargs)
  File "/home/rohit/Desktop/CRUD/env/lib/python3.6/site-packages/django/views/decorators/csrf.py", line 54, in wrapped_view
    return view_func(*args, **kwargs)
  File "/home/rohit/Desktop/CRUD/env/lib/python3.6/site-packages/rest_framework/viewsets.py", line 114, in view
    return self.dispatch(request, *args, **kwargs)
  File "/home/rohit/Desktop/CRUD/env/lib/python3.6/site-packages/rest_framework/views.py", line 505, in dispatch
    response = self.handle_exception(exc)
  File "/home/rohit/Desktop/CRUD/env/lib/python3.6/site-packages/rest_framework/views.py", line 465, in handle_exception
    self.raise_uncaught_exception(exc)
  File "/home/rohit/Desktop/CRUD/env/lib/python3.6/site-packages/rest_framework/views.py", line 476, in raise_uncaught_exception
    raise exc
  File "/home/rohit/Desktop/CRUD/env/lib/python3.6/site-packages/rest_framework/views.py", line 502, in dispatch
    response = handler(request, *args, **kwargs)
  File "/home/rohit/Desktop/CRUD/env/lib/python3.6/site-packages/rest_framework/mixins.py", line 19, in create
    self.perform_create(serializer)
  File "/home/rohit/Desktop/CRUD/env/lib/python3.6/site-packages/rest_framework/mixins.py", line 24, in perform_create
    serializer.save()
  File "/home/rohit/Desktop/CRUD/env/lib/python3.6/site-packages/rest_framework/serializers.py", line 212, in save
    self.instance = self.create(validated_data)
  File "/home/rohit/Desktop/CRUD/env/lib/python3.6/site-packages/rest_framework/serializers.py", line 948, in create
    instance = ModelClass._default_manager.create(**validated_data)
  File "/home/rohit/Desktop/CRUD/env/lib/python3.6/site-packages/django/db/models/manager.py", line 85, in manager_method
    return getattr(self.get_queryset(), name)(*args, **kwargs)
  File "/home/rohit/Desktop/CRUD/env/lib/python3.6/site-packages/django/db/models/query.py", line 447, in create
    obj.save(force_insert=True, using=self.db)
  File "/home/rohit/Desktop/CRUD/env/lib/python3.6/site-packages/django/db/models/base.py", line 754, in save
    force_update=force_update, update_fields=update_fields)
  File "/home/rohit/Desktop/CRUD/env/lib/python3.6/site-packages/django/db/models/base.py", line 792, in save_base
    force_update, using, update_fields,
  File "/home/rohit/Desktop/CRUD/env/lib/python3.6/site-packages/django/db/models/base.py", line 895, in _save_table
    results = self._do_insert(cls._base_manager, using, fields, returning_fields, raw)
  File "/home/rohit/Desktop/CRUD/env/lib/python3.6/site-packages/django/db/models/base.py", line 935, in _do_insert
    using=using, raw=raw,
  File "/home/rohit/Desktop/CRUD/env/lib/python3.6/site-packages/django/db/models/manager.py", line 85, in manager_method
    return getattr(self.get_queryset(), name)(*args, **kwargs)
  File "/home/rohit/Desktop/CRUD/env/lib/python3.6/site-packages/django/db/models/query.py", line 1249, in _insert
    return query.get_compiler(using=using).execute_sql(returning_fields)
  File "/home/rohit/Desktop/CRUD/env/lib/python3.6/site-packages/django/db/models/sql/compiler.py", line 1397, in execute_sql
    cursor.execute(sql, params)
  File "/home/rohit/Desktop/CRUD/env/lib/python3.6/site-packages/django/db/backends/utils.py", line 98, in execute
    return super().execute(sql, params)
  File "/home/rohit/Desktop/CRUD/env/lib/python3.6/site-packages/django/db/backends/utils.py", line 66, in execute
    return self._execute_with_wrappers(sql, params, many=False, executor=self._execute)
  File "/home/rohit/Desktop/CRUD/env/lib/python3.6/site-packages/django/db/backends/utils.py", line 75, in _execute_with_wrappers
    return executor(sql, params, many, context)
  File "/home/rohit/Desktop/CRUD/env/lib/python3.6/site-packages/django/db/backends/utils.py", line 84, in _execute
    return self.cursor.execute(sql, params)
  File "/home/rohit/Desktop/CRUD/env/lib/python3.6/site-packages/django/db/backends/mysql/base.py", line 78, in execute
    raise IntegrityError(*tuple(e.args))
django.db.utils.IntegrityError: (1048, "Column 'student_weight' cannot be null")
2020-11-13 16:17:21,644 [ERROR] {/home/rohit/Desktop/CRUD/env/lib/python3.6/site-packages/django/utils/log.py:230} : Internal Server Error: /district/View_Set/TVS/
Traceback (most recent call last):
  File "/home/rohit/Desktop/CRUD/env/lib/python3.6/site-packages/django/db/backends/mysql/base.py", line 73, in execute
    return self.cursor.execute(query, args)
  File "/home/rohit/Desktop/CRUD/env/lib/python3.6/site-packages/MySQLdb/cursors.py", line 209, in execute
    res = self._query(query)
  File "/home/rohit/Desktop/CRUD/env/lib/python3.6/site-packages/MySQLdb/cursors.py", line 315, in _query
    db.query(q)
  File "/home/rohit/Desktop/CRUD/env/lib/python3.6/site-packages/MySQLdb/connections.py", line 239, in query
    _mysql.connection.query(self, query)
MySQLdb._exceptions.OperationalError: (1048, "Column 'student_weight' cannot be null")

During handling of the above exception, another exception occurred:

Traceback (most recent call last):
  File "/home/rohit/Desktop/CRUD/env/lib/python3.6/site-packages/django/core/handlers/exception.py", line 47, in inner
    response = get_response(request)
  File "/home/rohit/Desktop/CRUD/env/lib/python3.6/site-packages/django/core/handlers/base.py", line 179, in _get_response
    response = wrapped_callback(request, *callback_args, **callback_kwargs)
  File "/home/rohit/Desktop/CRUD/env/lib/python3.6/site-packages/django/views/decorators/csrf.py", line 54, in wrapped_view
    return view_func(*args, **kwargs)
  File "/home/rohit/Desktop/CRUD/env/lib/python3.6/site-packages/rest_framework/viewsets.py", line 114, in view
    return self.dispatch(request, *args, **kwargs)
  File "/home/rohit/Desktop/CRUD/env/lib/python3.6/site-packages/rest_framework/views.py", line 505, in dispatch
    response = self.handle_exception(exc)
  File "/home/rohit/Desktop/CRUD/env/lib/python3.6/site-packages/rest_framework/views.py", line 465, in handle_exception
    self.raise_uncaught_exception(exc)
  File "/home/rohit/Desktop/CRUD/env/lib/python3.6/site-packages/rest_framework/views.py", line 476, in raise_uncaught_exception
    raise exc
  File "/home/rohit/Desktop/CRUD/env/lib/python3.6/site-packages/rest_framework/views.py", line 502, in dispatch
    response = handler(request, *args, **kwargs)
  File "/home/rohit/Desktop/CRUD/env/lib/python3.6/site-packages/rest_framework/mixins.py", line 19, in create
    self.perform_create(serializer)
  File "/home/rohit/Desktop/CRUD/env/lib/python3.6/site-packages/rest_framework/mixins.py", line 24, in perform_create
    serializer.save()
  File "/home/rohit/Desktop/CRUD/env/lib/python3.6/site-packages/rest_framework/serializers.py", line 212, in save
    self.instance = self.create(validated_data)
  File "/home/rohit/Desktop/CRUD/env/lib/python3.6/site-packages/rest_framework/serializers.py", line 948, in create
    instance = ModelClass._default_manager.create(**validated_data)
  File "/home/rohit/Desktop/CRUD/env/lib/python3.6/site-packages/django/db/models/manager.py", line 85, in manager_method
    return getattr(self.get_queryset(), name)(*args, **kwargs)
  File "/home/rohit/Desktop/CRUD/env/lib/python3.6/site-packages/django/db/models/query.py", line 447, in create
    obj.save(force_insert=True, using=self.db)
  File "/home/rohit/Desktop/CRUD/env/lib/python3.6/site-packages/django/db/models/base.py", line 754, in save
    force_update=force_update, update_fields=update_fields)
  File "/home/rohit/Desktop/CRUD/env/lib/python3.6/site-packages/django/db/models/base.py", line 792, in save_base
    force_update, using, update_fields,
  File "/home/rohit/Desktop/CRUD/env/lib/python3.6/site-packages/django/db/models/base.py", line 895, in _save_table
    results = self._do_insert(cls._base_manager, using, fields, returning_fields, raw)
  File "/home/rohit/Desktop/CRUD/env/lib/python3.6/site-packages/django/db/models/base.py", line 935, in _do_insert
    using=using, raw=raw,
  File "/home/rohit/Desktop/CRUD/env/lib/python3.6/site-packages/django/db/models/manager.py", line 85, in manager_method
    return getattr(self.get_queryset(), name)(*args, **kwargs)
  File "/home/rohit/Desktop/CRUD/env/lib/python3.6/site-packages/django/db/models/query.py", line 1249, in _insert
    return query.get_compiler(using=using).execute_sql(returning_fields)
  File "/home/rohit/Desktop/CRUD/env/lib/python3.6/site-packages/django/db/models/sql/compiler.py", line 1397, in execute_sql
    cursor.execute(sql, params)
  File "/home/rohit/Desktop/CRUD/env/lib/python3.6/site-packages/django/db/backends/utils.py", line 98, in execute
    return super().execute(sql, params)
  File "/home/rohit/Desktop/CRUD/env/lib/python3.6/site-packages/django/db/backends/utils.py", line 66, in execute
    return self._execute_with_wrappers(sql, params, many=False, executor=self._execute)
  File "/home/rohit/Desktop/CRUD/env/lib/python3.6/site-packages/django/db/backends/utils.py", line 75, in _execute_with_wrappers
    return executor(sql, params, many, context)
  File "/home/rohit/Desktop/CRUD/env/lib/python3.6/site-packages/django/db/backends/utils.py", line 84, in _execute
    return self.cursor.execute(sql, params)
  File "/home/rohit/Desktop/CRUD/env/lib/python3.6/site-packages/django/db/backends/mysql/base.py", line 78, in execute
    raise IntegrityError(*tuple(e.args))
django.db.utils.IntegrityError: (1048, "Column 'student_weight' cannot be null")
2020-11-13 16:17:53,444 [ERROR] {/home/rohit/Desktop/CRUD/env/lib/python3.6/site-packages/django/utils/log.py:230} : Internal Server Error: /district/View_Set/TVS/
Traceback (most recent call last):
  File "/home/rohit/Desktop/CRUD/env/lib/python3.6/site-packages/django/db/backends/utils.py", line 84, in _execute
    return self.cursor.execute(sql, params)
  File "/home/rohit/Desktop/CRUD/env/lib/python3.6/site-packages/django/db/backends/mysql/base.py", line 73, in execute
    return self.cursor.execute(query, args)
  File "/home/rohit/Desktop/CRUD/env/lib/python3.6/site-packages/MySQLdb/cursors.py", line 209, in execute
    res = self._query(query)
  File "/home/rohit/Desktop/CRUD/env/lib/python3.6/site-packages/MySQLdb/cursors.py", line 315, in _query
    db.query(q)
  File "/home/rohit/Desktop/CRUD/env/lib/python3.6/site-packages/MySQLdb/connections.py", line 239, in query
    _mysql.connection.query(self, query)
MySQLdb._exceptions.IntegrityError: (1364, "Field 'student_height' doesn't have a default value")

The above exception was the direct cause of the following exception:

Traceback (most recent call last):
  File "/home/rohit/Desktop/CRUD/env/lib/python3.6/site-packages/django/core/handlers/exception.py", line 47, in inner
    response = get_response(request)
  File "/home/rohit/Desktop/CRUD/env/lib/python3.6/site-packages/django/core/handlers/base.py", line 179, in _get_response
    response = wrapped_callback(request, *callback_args, **callback_kwargs)
  File "/home/rohit/Desktop/CRUD/env/lib/python3.6/site-packages/django/views/decorators/csrf.py", line 54, in wrapped_view
    return view_func(*args, **kwargs)
  File "/home/rohit/Desktop/CRUD/env/lib/python3.6/site-packages/rest_framework/viewsets.py", line 114, in view
    return self.dispatch(request, *args, **kwargs)
  File "/home/rohit/Desktop/CRUD/env/lib/python3.6/site-packages/rest_framework/views.py", line 505, in dispatch
    response = self.handle_exception(exc)
  File "/home/rohit/Desktop/CRUD/env/lib/python3.6/site-packages/rest_framework/views.py", line 465, in handle_exception
    self.raise_uncaught_exception(exc)
  File "/home/rohit/Desktop/CRUD/env/lib/python3.6/site-packages/rest_framework/views.py", line 476, in raise_uncaught_exception
    raise exc
  File "/home/rohit/Desktop/CRUD/env/lib/python3.6/site-packages/rest_framework/views.py", line 502, in dispatch
    response = handler(request, *args, **kwargs)
  File "/home/rohit/Desktop/CRUD/env/lib/python3.6/site-packages/rest_framework/mixins.py", line 19, in create
    self.perform_create(serializer)
  File "/home/rohit/Desktop/CRUD/env/lib/python3.6/site-packages/rest_framework/mixins.py", line 24, in perform_create
    serializer.save()
  File "/home/rohit/Desktop/CRUD/env/lib/python3.6/site-packages/rest_framework/serializers.py", line 212, in save
    self.instance = self.create(validated_data)
  File "/home/rohit/Desktop/CRUD/env/lib/python3.6/site-packages/rest_framework/serializers.py", line 948, in create
    instance = ModelClass._default_manager.create(**validated_data)
  File "/home/rohit/Desktop/CRUD/env/lib/python3.6/site-packages/django/db/models/manager.py", line 85, in manager_method
    return getattr(self.get_queryset(), name)(*args, **kwargs)
  File "/home/rohit/Desktop/CRUD/env/lib/python3.6/site-packages/django/db/models/query.py", line 447, in create
    obj.save(force_insert=True, using=self.db)
  File "/home/rohit/Desktop/CRUD/env/lib/python3.6/site-packages/django/db/models/base.py", line 754, in save
    force_update=force_update, update_fields=update_fields)
  File "/home/rohit/Desktop/CRUD/env/lib/python3.6/site-packages/django/db/models/base.py", line 792, in save_base
    force_update, using, update_fields,
  File "/home/rohit/Desktop/CRUD/env/lib/python3.6/site-packages/django/db/models/base.py", line 895, in _save_table
    results = self._do_insert(cls._base_manager, using, fields, returning_fields, raw)
  File "/home/rohit/Desktop/CRUD/env/lib/python3.6/site-packages/django/db/models/base.py", line 935, in _do_insert
    using=using, raw=raw,
  File "/home/rohit/Desktop/CRUD/env/lib/python3.6/site-packages/django/db/models/manager.py", line 85, in manager_method
    return getattr(self.get_queryset(), name)(*args, **kwargs)
  File "/home/rohit/Desktop/CRUD/env/lib/python3.6/site-packages/django/db/models/query.py", line 1249, in _insert
    return query.get_compiler(using=using).execute_sql(returning_fields)
  File "/home/rohit/Desktop/CRUD/env/lib/python3.6/site-packages/django/db/models/sql/compiler.py", line 1397, in execute_sql
    cursor.execute(sql, params)
  File "/home/rohit/Desktop/CRUD/env/lib/python3.6/site-packages/django/db/backends/utils.py", line 98, in execute
    return super().execute(sql, params)
  File "/home/rohit/Desktop/CRUD/env/lib/python3.6/site-packages/django/db/backends/utils.py", line 66, in execute
    return self._execute_with_wrappers(sql, params, many=False, executor=self._execute)
  File "/home/rohit/Desktop/CRUD/env/lib/python3.6/site-packages/django/db/backends/utils.py", line 75, in _execute_with_wrappers
    return executor(sql, params, many, context)
  File "/home/rohit/Desktop/CRUD/env/lib/python3.6/site-packages/django/db/backends/utils.py", line 84, in _execute
    return self.cursor.execute(sql, params)
  File "/home/rohit/Desktop/CRUD/env/lib/python3.6/site-packages/django/db/utils.py", line 90, in __exit__
    raise dj_exc_value.with_traceback(traceback) from exc_value
  File "/home/rohit/Desktop/CRUD/env/lib/python3.6/site-packages/django/db/backends/utils.py", line 84, in _execute
    return self.cursor.execute(sql, params)
  File "/home/rohit/Desktop/CRUD/env/lib/python3.6/site-packages/django/db/backends/mysql/base.py", line 73, in execute
    return self.cursor.execute(query, args)
  File "/home/rohit/Desktop/CRUD/env/lib/python3.6/site-packages/MySQLdb/cursors.py", line 209, in execute
    res = self._query(query)
  File "/home/rohit/Desktop/CRUD/env/lib/python3.6/site-packages/MySQLdb/cursors.py", line 315, in _query
    db.query(q)
  File "/home/rohit/Desktop/CRUD/env/lib/python3.6/site-packages/MySQLdb/connections.py", line 239, in query
    _mysql.connection.query(self, query)
django.db.utils.IntegrityError: (1364, "Field 'student_height' doesn't have a default value")
2020-11-13 16:18:27,343 [ERROR] {/home/rohit/Desktop/CRUD/env/lib/python3.6/site-packages/django/utils/log.py:230} : Internal Server Error: /district/View_Set/TVS/
Traceback (most recent call last):
  File "/home/rohit/Desktop/CRUD/env/lib/python3.6/site-packages/django/db/backends/utils.py", line 84, in _execute
    return self.cursor.execute(sql, params)
  File "/home/rohit/Desktop/CRUD/env/lib/python3.6/site-packages/django/db/backends/mysql/base.py", line 73, in execute
    return self.cursor.execute(query, args)
  File "/home/rohit/Desktop/CRUD/env/lib/python3.6/site-packages/MySQLdb/cursors.py", line 209, in execute
    res = self._query(query)
  File "/home/rohit/Desktop/CRUD/env/lib/python3.6/site-packages/MySQLdb/cursors.py", line 315, in _query
    db.query(q)
  File "/home/rohit/Desktop/CRUD/env/lib/python3.6/site-packages/MySQLdb/connections.py", line 239, in query
    _mysql.connection.query(self, query)
MySQLdb._exceptions.IntegrityError: (1364, "Field 'student_height' doesn't have a default value")

The above exception was the direct cause of the following exception:

Traceback (most recent call last):
  File "/home/rohit/Desktop/CRUD/env/lib/python3.6/site-packages/django/core/handlers/exception.py", line 47, in inner
    response = get_response(request)
  File "/home/rohit/Desktop/CRUD/env/lib/python3.6/site-packages/django/core/handlers/base.py", line 179, in _get_response
    response = wrapped_callback(request, *callback_args, **callback_kwargs)
  File "/home/rohit/Desktop/CRUD/env/lib/python3.6/site-packages/django/views/decorators/csrf.py", line 54, in wrapped_view
    return view_func(*args, **kwargs)
  File "/home/rohit/Desktop/CRUD/env/lib/python3.6/site-packages/rest_framework/viewsets.py", line 114, in view
    return self.dispatch(request, *args, **kwargs)
  File "/home/rohit/Desktop/CRUD/env/lib/python3.6/site-packages/rest_framework/views.py", line 505, in dispatch
    response = self.handle_exception(exc)
  File "/home/rohit/Desktop/CRUD/env/lib/python3.6/site-packages/rest_framework/views.py", line 465, in handle_exception
    self.raise_uncaught_exception(exc)
  File "/home/rohit/Desktop/CRUD/env/lib/python3.6/site-packages/rest_framework/views.py", line 476, in raise_uncaught_exception
    raise exc
  File "/home/rohit/Desktop/CRUD/env/lib/python3.6/site-packages/rest_framework/views.py", line 502, in dispatch
    response = handler(request, *args, **kwargs)
  File "/home/rohit/Desktop/CRUD/env/lib/python3.6/site-packages/rest_framework/mixins.py", line 19, in create
    self.perform_create(serializer)
  File "/home/rohit/Desktop/CRUD/env/lib/python3.6/site-packages/rest_framework/mixins.py", line 24, in perform_create
    serializer.save()
  File "/home/rohit/Desktop/CRUD/env/lib/python3.6/site-packages/rest_framework/serializers.py", line 212, in save
    self.instance = self.create(validated_data)
  File "/home/rohit/Desktop/CRUD/env/lib/python3.6/site-packages/rest_framework/serializers.py", line 948, in create
    instance = ModelClass._default_manager.create(**validated_data)
  File "/home/rohit/Desktop/CRUD/env/lib/python3.6/site-packages/django/db/models/manager.py", line 85, in manager_method
    return getattr(self.get_queryset(), name)(*args, **kwargs)
  File "/home/rohit/Desktop/CRUD/env/lib/python3.6/site-packages/django/db/models/query.py", line 447, in create
    obj.save(force_insert=True, using=self.db)
  File "/home/rohit/Desktop/CRUD/env/lib/python3.6/site-packages/django/db/models/base.py", line 754, in save
    force_update=force_update, update_fields=update_fields)
  File "/home/rohit/Desktop/CRUD/env/lib/python3.6/site-packages/django/db/models/base.py", line 792, in save_base
    force_update, using, update_fields,
  File "/home/rohit/Desktop/CRUD/env/lib/python3.6/site-packages/django/db/models/base.py", line 895, in _save_table
    results = self._do_insert(cls._base_manager, using, fields, returning_fields, raw)
  File "/home/rohit/Desktop/CRUD/env/lib/python3.6/site-packages/django/db/models/base.py", line 935, in _do_insert
    using=using, raw=raw,
  File "/home/rohit/Desktop/CRUD/env/lib/python3.6/site-packages/django/db/models/manager.py", line 85, in manager_method
    return getattr(self.get_queryset(), name)(*args, **kwargs)
  File "/home/rohit/Desktop/CRUD/env/lib/python3.6/site-packages/django/db/models/query.py", line 1249, in _insert
    return query.get_compiler(using=using).execute_sql(returning_fields)
  File "/home/rohit/Desktop/CRUD/env/lib/python3.6/site-packages/django/db/models/sql/compiler.py", line 1397, in execute_sql
    cursor.execute(sql, params)
  File "/home/rohit/Desktop/CRUD/env/lib/python3.6/site-packages/django/db/backends/utils.py", line 98, in execute
    return super().execute(sql, params)
  File "/home/rohit/Desktop/CRUD/env/lib/python3.6/site-packages/django/db/backends/utils.py", line 66, in execute
    return self._execute_with_wrappers(sql, params, many=False, executor=self._execute)
  File "/home/rohit/Desktop/CRUD/env/lib/python3.6/site-packages/django/db/backends/utils.py", line 75, in _execute_with_wrappers
    return executor(sql, params, many, context)
  File "/home/rohit/Desktop/CRUD/env/lib/python3.6/site-packages/django/db/backends/utils.py", line 84, in _execute
    return self.cursor.execute(sql, params)
  File "/home/rohit/Desktop/CRUD/env/lib/python3.6/site-packages/django/db/utils.py", line 90, in __exit__
    raise dj_exc_value.with_traceback(traceback) from exc_value
  File "/home/rohit/Desktop/CRUD/env/lib/python3.6/site-packages/django/db/backends/utils.py", line 84, in _execute
    return self.cursor.execute(sql, params)
  File "/home/rohit/Desktop/CRUD/env/lib/python3.6/site-packages/django/db/backends/mysql/base.py", line 73, in execute
    return self.cursor.execute(query, args)
  File "/home/rohit/Desktop/CRUD/env/lib/python3.6/site-packages/MySQLdb/cursors.py", line 209, in execute
    res = self._query(query)
  File "/home/rohit/Desktop/CRUD/env/lib/python3.6/site-packages/MySQLdb/cursors.py", line 315, in _query
    db.query(q)
  File "/home/rohit/Desktop/CRUD/env/lib/python3.6/site-packages/MySQLdb/connections.py", line 239, in query
    _mysql.connection.query(self, query)
django.db.utils.IntegrityError: (1364, "Field 'student_height' doesn't have a default value")
2020-11-13 16:18:47,683 [ERROR] {/home/rohit/Desktop/CRUD/env/lib/python3.6/site-packages/django/utils/log.py:230} : Internal Server Error: /district/View_Set/TVS/
Traceback (most recent call last):
  File "/home/rohit/Desktop/CRUD/env/lib/python3.6/site-packages/django/core/handlers/exception.py", line 47, in inner
    response = get_response(request)
  File "/home/rohit/Desktop/CRUD/env/lib/python3.6/site-packages/django/core/handlers/base.py", line 179, in _get_response
    response = wrapped_callback(request, *callback_args, **callback_kwargs)
  File "/home/rohit/Desktop/CRUD/env/lib/python3.6/site-packages/django/views/decorators/csrf.py", line 54, in wrapped_view
    return view_func(*args, **kwargs)
  File "/home/rohit/Desktop/CRUD/env/lib/python3.6/site-packages/rest_framework/viewsets.py", line 114, in view
    return self.dispatch(request, *args, **kwargs)
  File "/home/rohit/Desktop/CRUD/env/lib/python3.6/site-packages/rest_framework/views.py", line 505, in dispatch
    response = self.handle_exception(exc)
  File "/home/rohit/Desktop/CRUD/env/lib/python3.6/site-packages/rest_framework/views.py", line 465, in handle_exception
    self.raise_uncaught_exception(exc)
  File "/home/rohit/Desktop/CRUD/env/lib/python3.6/site-packages/rest_framework/views.py", line 476, in raise_uncaught_exception
    raise exc
  File "/home/rohit/Desktop/CRUD/env/lib/python3.6/site-packages/rest_framework/views.py", line 502, in dispatch
    response = handler(request, *args, **kwargs)
  File "/home/rohit/Desktop/CRUD/env/lib/python3.6/site-packages/rest_framework/mixins.py", line 18, in create
    serializer.is_valid(raise_exception=True)
  File "/home/rohit/Desktop/CRUD/env/lib/python3.6/site-packages/rest_framework/serializers.py", line 234, in is_valid
    self._validated_data = self.run_validation(self.initial_data)
  File "/home/rohit/Desktop/CRUD/env/lib/python3.6/site-packages/rest_framework/serializers.py", line 433, in run_validation
    value = self.to_internal_value(data)
  File "/home/rohit/Desktop/CRUD/env/lib/python3.6/site-packages/rest_framework/serializers.py", line 486, in to_internal_value
    for field in fields:
  File "/home/rohit/Desktop/CRUD/env/lib/python3.6/site-packages/rest_framework/serializers.py", line 369, in _writable_fields
    for field in self.fields.values():
  File "/home/rohit/Desktop/CRUD/env/lib/python3.6/site-packages/django/utils/functional.py", line 48, in __get__
    res = instance.__dict__[self.name] = self.func(instance)
  File "/home/rohit/Desktop/CRUD/env/lib/python3.6/site-packages/rest_framework/serializers.py", line 363, in fields
    for key, value in self.get_fields().items():
  File "/home/rohit/Desktop/CRUD/env/lib/python3.6/site-packages/rest_framework/serializers.py", line 1063, in get_fields
    source, info, model, depth
  File "/home/rohit/Desktop/CRUD/env/lib/python3.6/site-packages/rest_framework/serializers.py", line 1208, in build_field
    return self.build_unknown_field(field_name, model_class)
  File "/home/rohit/Desktop/CRUD/env/lib/python3.6/site-packages/rest_framework/serializers.py", line 1325, in build_unknown_field
    (field_name, model_class.__name__)
django.core.exceptions.ImproperlyConfigured: Field name `student_height` is not valid for model `Student`.
2020-11-13 16:19:04,687 [ERROR] {/home/rohit/Desktop/CRUD/env/lib/python3.6/site-packages/django/utils/log.py:230} : Internal Server Error: /district/View_Set/TVS/
Traceback (most recent call last):
  File "/home/rohit/Desktop/CRUD/env/lib/python3.6/site-packages/django/core/handlers/exception.py", line 47, in inner
    response = get_response(request)
  File "/home/rohit/Desktop/CRUD/env/lib/python3.6/site-packages/django/core/handlers/base.py", line 179, in _get_response
    response = wrapped_callback(request, *callback_args, **callback_kwargs)
  File "/home/rohit/Desktop/CRUD/env/lib/python3.6/site-packages/django/views/decorators/csrf.py", line 54, in wrapped_view
    return view_func(*args, **kwargs)
  File "/home/rohit/Desktop/CRUD/env/lib/python3.6/site-packages/rest_framework/viewsets.py", line 114, in view
    return self.dispatch(request, *args, **kwargs)
  File "/home/rohit/Desktop/CRUD/env/lib/python3.6/site-packages/rest_framework/views.py", line 505, in dispatch
    response = self.handle_exception(exc)
  File "/home/rohit/Desktop/CRUD/env/lib/python3.6/site-packages/rest_framework/views.py", line 465, in handle_exception
    self.raise_uncaught_exception(exc)
  File "/home/rohit/Desktop/CRUD/env/lib/python3.6/site-packages/rest_framework/views.py", line 476, in raise_uncaught_exception
    raise exc
  File "/home/rohit/Desktop/CRUD/env/lib/python3.6/site-packages/rest_framework/views.py", line 502, in dispatch
    response = handler(request, *args, **kwargs)
  File "/home/rohit/Desktop/CRUD/env/lib/python3.6/site-packages/rest_framework/mixins.py", line 18, in create
    serializer.is_valid(raise_exception=True)
  File "/home/rohit/Desktop/CRUD/env/lib/python3.6/site-packages/rest_framework/serializers.py", line 234, in is_valid
    self._validated_data = self.run_validation(self.initial_data)
  File "/home/rohit/Desktop/CRUD/env/lib/python3.6/site-packages/rest_framework/serializers.py", line 433, in run_validation
    value = self.to_internal_value(data)
  File "/home/rohit/Desktop/CRUD/env/lib/python3.6/site-packages/rest_framework/serializers.py", line 486, in to_internal_value
    for field in fields:
  File "/home/rohit/Desktop/CRUD/env/lib/python3.6/site-packages/rest_framework/serializers.py", line 369, in _writable_fields
    for field in self.fields.values():
  File "/home/rohit/Desktop/CRUD/env/lib/python3.6/site-packages/django/utils/functional.py", line 48, in __get__
    res = instance.__dict__[self.name] = self.func(instance)
  File "/home/rohit/Desktop/CRUD/env/lib/python3.6/site-packages/rest_framework/serializers.py", line 363, in fields
    for key, value in self.get_fields().items():
  File "/home/rohit/Desktop/CRUD/env/lib/python3.6/site-packages/rest_framework/serializers.py", line 1063, in get_fields
    source, info, model, depth
  File "/home/rohit/Desktop/CRUD/env/lib/python3.6/site-packages/rest_framework/serializers.py", line 1208, in build_field
    return self.build_unknown_field(field_name, model_class)
  File "/home/rohit/Desktop/CRUD/env/lib/python3.6/site-packages/rest_framework/serializers.py", line 1325, in build_unknown_field
    (field_name, model_class.__name__)
django.core.exceptions.ImproperlyConfigured: Field name `student_height` is not valid for model `Student`.
2020-11-13 16:19:14,043 [ERROR] {/home/rohit/Desktop/CRUD/env/lib/python3.6/site-packages/django/utils/log.py:230} : Internal Server Error: /district/View_Set/TVS/
Traceback (most recent call last):
  File "/home/rohit/Desktop/CRUD/env/lib/python3.6/site-packages/django/core/handlers/exception.py", line 47, in inner
    response = get_response(request)
  File "/home/rohit/Desktop/CRUD/env/lib/python3.6/site-packages/django/core/handlers/base.py", line 179, in _get_response
    response = wrapped_callback(request, *callback_args, **callback_kwargs)
  File "/home/rohit/Desktop/CRUD/env/lib/python3.6/site-packages/django/views/decorators/csrf.py", line 54, in wrapped_view
    return view_func(*args, **kwargs)
  File "/home/rohit/Desktop/CRUD/env/lib/python3.6/site-packages/rest_framework/viewsets.py", line 114, in view
    return self.dispatch(request, *args, **kwargs)
  File "/home/rohit/Desktop/CRUD/env/lib/python3.6/site-packages/rest_framework/views.py", line 505, in dispatch
    response = self.handle_exception(exc)
  File "/home/rohit/Desktop/CRUD/env/lib/python3.6/site-packages/rest_framework/views.py", line 465, in handle_exception
    self.raise_uncaught_exception(exc)
  File "/home/rohit/Desktop/CRUD/env/lib/python3.6/site-packages/rest_framework/views.py", line 476, in raise_uncaught_exception
    raise exc
  File "/home/rohit/Desktop/CRUD/env/lib/python3.6/site-packages/rest_framework/views.py", line 502, in dispatch
    response = handler(request, *args, **kwargs)
  File "/home/rohit/Desktop/CRUD/env/lib/python3.6/site-packages/rest_framework/mixins.py", line 18, in create
    serializer.is_valid(raise_exception=True)
  File "/home/rohit/Desktop/CRUD/env/lib/python3.6/site-packages/rest_framework/serializers.py", line 234, in is_valid
    self._validated_data = self.run_validation(self.initial_data)
  File "/home/rohit/Desktop/CRUD/env/lib/python3.6/site-packages/rest_framework/serializers.py", line 433, in run_validation
    value = self.to_internal_value(data)
  File "/home/rohit/Desktop/CRUD/env/lib/python3.6/site-packages/rest_framework/serializers.py", line 486, in to_internal_value
    for field in fields:
  File "/home/rohit/Desktop/CRUD/env/lib/python3.6/site-packages/rest_framework/serializers.py", line 369, in _writable_fields
    for field in self.fields.values():
  File "/home/rohit/Desktop/CRUD/env/lib/python3.6/site-packages/django/utils/functional.py", line 48, in __get__
    res = instance.__dict__[self.name] = self.func(instance)
  File "/home/rohit/Desktop/CRUD/env/lib/python3.6/site-packages/rest_framework/serializers.py", line 363, in fields
    for key, value in self.get_fields().items():
  File "/home/rohit/Desktop/CRUD/env/lib/python3.6/site-packages/rest_framework/serializers.py", line 1063, in get_fields
    source, info, model, depth
  File "/home/rohit/Desktop/CRUD/env/lib/python3.6/site-packages/rest_framework/serializers.py", line 1208, in build_field
    return self.build_unknown_field(field_name, model_class)
  File "/home/rohit/Desktop/CRUD/env/lib/python3.6/site-packages/rest_framework/serializers.py", line 1325, in build_unknown_field
    (field_name, model_class.__name__)
django.core.exceptions.ImproperlyConfigured: Field name `student_height` is not valid for model `Student`.
2020-11-13 16:22:52,622 [ERROR] {/home/rohit/Desktop/CRUD/env/lib/python3.6/site-packages/django/utils/log.py:230} : Internal Server Error: /district/View_Set/TVS/roll_2
Traceback (most recent call last):
  File "/home/rohit/Desktop/CRUD/env/lib/python3.6/site-packages/django/core/handlers/exception.py", line 47, in inner
    response = get_response(request)
  File "/home/rohit/Desktop/CRUD/env/lib/python3.6/site-packages/django/utils/deprecation.py", line 113, in __call__
    response = self.process_request(request)
  File "/home/rohit/Desktop/CRUD/env/lib/python3.6/site-packages/django/middleware/common.py", line 54, in process_request
    path = self.get_full_path_with_slash(request)
  File "/home/rohit/Desktop/CRUD/env/lib/python3.6/site-packages/django/middleware/common.py", line 94, in get_full_path_with_slash
    'url': request.get_host() + new_path,
RuntimeError: You called this URL via PUT, but the URL doesn't end in a slash and you have APPEND_SLASH set. Django can't redirect to the slash URL while maintaining PUT data. Change your form to point to 127.0.0.1:8000/district/View_Set/TVS/roll_2/ (note the trailing slash), or set APPEND_SLASH=False in your Django settings.
2020-11-13 16:36:14,010 [ERROR] {/home/rohit/Desktop/CRUD/env/lib/python3.6/site-packages/django/utils/log.py:230} : Internal Server Error: /district/View_Set/TVS
Traceback (most recent call last):
  File "/home/rohit/Desktop/CRUD/env/lib/python3.6/site-packages/django/core/handlers/exception.py", line 47, in inner
    response = get_response(request)
  File "/home/rohit/Desktop/CRUD/env/lib/python3.6/site-packages/django/utils/deprecation.py", line 113, in __call__
    response = self.process_request(request)
  File "/home/rohit/Desktop/CRUD/env/lib/python3.6/site-packages/django/middleware/common.py", line 54, in process_request
    path = self.get_full_path_with_slash(request)
  File "/home/rohit/Desktop/CRUD/env/lib/python3.6/site-packages/django/middleware/common.py", line 94, in get_full_path_with_slash
    'url': request.get_host() + new_path,
RuntimeError: You called this URL via POST, but the URL doesn't end in a slash and you have APPEND_SLASH set. Django can't redirect to the slash URL while maintaining POST data. Change your form to point to 127.0.0.1:8000/district/View_Set/TVS/ (note the trailing slash), or set APPEND_SLASH=False in your Django settings.
2020-11-13 16:39:24,645 [ERROR] {/home/rohit/Desktop/CRUD/env/lib/python3.6/site-packages/django/utils/log.py:230} : Internal Server Error: /district/View_Set/TVS/1/
Traceback (most recent call last):
  File "/home/rohit/Desktop/CRUD/env/lib/python3.6/site-packages/django/core/handlers/exception.py", line 47, in inner
    response = get_response(request)
  File "/home/rohit/Desktop/CRUD/env/lib/python3.6/site-packages/django/core/handlers/base.py", line 179, in _get_response
    response = wrapped_callback(request, *callback_args, **callback_kwargs)
  File "/home/rohit/Desktop/CRUD/env/lib/python3.6/site-packages/django/views/decorators/csrf.py", line 54, in wrapped_view
    return view_func(*args, **kwargs)
  File "/home/rohit/Desktop/CRUD/env/lib/python3.6/site-packages/rest_framework/viewsets.py", line 114, in view
    return self.dispatch(request, *args, **kwargs)
  File "/home/rohit/Desktop/CRUD/env/lib/python3.6/site-packages/rest_framework/views.py", line 505, in dispatch
    response = self.handle_exception(exc)
  File "/home/rohit/Desktop/CRUD/env/lib/python3.6/site-packages/rest_framework/views.py", line 465, in handle_exception
    self.raise_uncaught_exception(exc)
  File "/home/rohit/Desktop/CRUD/env/lib/python3.6/site-packages/rest_framework/views.py", line 476, in raise_uncaught_exception
    raise exc
  File "/home/rohit/Desktop/CRUD/env/lib/python3.6/site-packages/rest_framework/views.py", line 502, in dispatch
    response = handler(request, *args, **kwargs)
TypeError: update() got an unexpected keyword argument 'roll_no'
2020-11-13 22:04:00,214 [ERROR] {/home/rohit/Desktop/CRUD/POLITICS/district/views.py:64} : list method is being called!!!
2020-11-13 22:04:56,053 [ERROR] {/home/rohit/Desktop/CRUD/POLITICS/district/views.py:64} : list method is being called!!!
2020-11-13 22:04:56,843 [ERROR] {/home/rohit/Desktop/CRUD/POLITICS/district/views.py:64} : list method is being called!!!
2020-11-13 22:11:50,357 [ERROR] {/home/rohit/Desktop/CRUD/POLITICS/district/views.py:67} : Exception occured is = division by zero
2020-11-13 22:13:20,021 [ERROR] {/home/rohit/Desktop/CRUD/POLITICS/district/views.py:67} : Exception occured is = division by zero
2020-11-13 22:13:20,174 [ERROR] {/home/rohit/Desktop/CRUD/env/lib/python3.6/site-packages/django/utils/log.py:230} : Internal Server Error: /district/View_Set/TVS/
Traceback (most recent call last):
  File "/home/rohit/Desktop/CRUD/POLITICS/district/views.py", line 65, in list
    a = 10 / 0
ZeroDivisionError: division by zero

During handling of the above exception, another exception occurred:

Traceback (most recent call last):
  File "/home/rohit/Desktop/CRUD/env/lib/python3.6/site-packages/django/core/handlers/exception.py", line 47, in inner
    response = get_response(request)
  File "/home/rohit/Desktop/CRUD/env/lib/python3.6/site-packages/django/core/handlers/base.py", line 179, in _get_response
    response = wrapped_callback(request, *callback_args, **callback_kwargs)
  File "/home/rohit/Desktop/CRUD/env/lib/python3.6/site-packages/django/views/decorators/csrf.py", line 54, in wrapped_view
    return view_func(*args, **kwargs)
  File "/home/rohit/Desktop/CRUD/env/lib/python3.6/site-packages/rest_framework/viewsets.py", line 114, in view
    return self.dispatch(request, *args, **kwargs)
  File "/home/rohit/Desktop/CRUD/env/lib/python3.6/site-packages/rest_framework/views.py", line 505, in dispatch
    response = self.handle_exception(exc)
  File "/home/rohit/Desktop/CRUD/env/lib/python3.6/site-packages/rest_framework/views.py", line 465, in handle_exception
    self.raise_uncaught_exception(exc)
  File "/home/rohit/Desktop/CRUD/env/lib/python3.6/site-packages/rest_framework/views.py", line 476, in raise_uncaught_exception
    raise exc
  File "/home/rohit/Desktop/CRUD/env/lib/python3.6/site-packages/rest_framework/views.py", line 502, in dispatch
    response = handler(request, *args, **kwargs)
  File "/home/rohit/Desktop/CRUD/POLITICS/district/views.py", line 68, in list
    raise serializers.ParseError({'a': 10})
AttributeError: module 'rest_framework.serializers' has no attribute 'ParseError'
2020-11-13 22:14:21,338 [ERROR] {/home/rohit/Desktop/CRUD/POLITICS/district/views.py:67} : Exception occured is = division by zero
2020-11-13 22:14:21,497 [ERROR] {/home/rohit/Desktop/CRUD/env/lib/python3.6/site-packages/django/utils/log.py:230} : Internal Server Error: /district/View_Set/TVS/
Traceback (most recent call last):
  File "/home/rohit/Desktop/CRUD/POLITICS/district/views.py", line 65, in list
    a = 10 / 0
ZeroDivisionError: division by zero

During handling of the above exception, another exception occurred:

Traceback (most recent call last):
  File "/home/rohit/Desktop/CRUD/env/lib/python3.6/site-packages/django/core/handlers/exception.py", line 47, in inner
    response = get_response(request)
  File "/home/rohit/Desktop/CRUD/env/lib/python3.6/site-packages/django/core/handlers/base.py", line 179, in _get_response
    response = wrapped_callback(request, *callback_args, **callback_kwargs)
  File "/home/rohit/Desktop/CRUD/env/lib/python3.6/site-packages/django/views/decorators/csrf.py", line 54, in wrapped_view
    return view_func(*args, **kwargs)
  File "/home/rohit/Desktop/CRUD/env/lib/python3.6/site-packages/rest_framework/viewsets.py", line 114, in view
    return self.dispatch(request, *args, **kwargs)
  File "/home/rohit/Desktop/CRUD/env/lib/python3.6/site-packages/rest_framework/views.py", line 505, in dispatch
    response = self.handle_exception(exc)
  File "/home/rohit/Desktop/CRUD/env/lib/python3.6/site-packages/rest_framework/views.py", line 465, in handle_exception
    self.raise_uncaught_exception(exc)
  File "/home/rohit/Desktop/CRUD/env/lib/python3.6/site-packages/rest_framework/views.py", line 476, in raise_uncaught_exception
    raise exc
  File "/home/rohit/Desktop/CRUD/env/lib/python3.6/site-packages/rest_framework/views.py", line 502, in dispatch
    response = handler(request, *args, **kwargs)
  File "/home/rohit/Desktop/CRUD/POLITICS/district/views.py", line 68, in list
    raise serializers.ParseError("Internal Server Error", status.HTTP_500_INTERNAL_SERVER_ERROR)
AttributeError: module 'rest_framework.serializers' has no attribute 'ParseError'
2020-11-13 22:14:44,464 [ERROR] {/home/rohit/Desktop/CRUD/POLITICS/district/views.py:67} : Exception occured is = division by zero
2020-11-13 22:14:44,618 [ERROR] {/home/rohit/Desktop/CRUD/env/lib/python3.6/site-packages/django/utils/log.py:230} : Internal Server Error: /district/View_Set/TVS/
Traceback (most recent call last):
  File "/home/rohit/Desktop/CRUD/POLITICS/district/views.py", line 65, in list
    a = 10 / 0
ZeroDivisionError: division by zero

During handling of the above exception, another exception occurred:

Traceback (most recent call last):
  File "/home/rohit/Desktop/CRUD/env/lib/python3.6/site-packages/django/core/handlers/exception.py", line 47, in inner
    response = get_response(request)
  File "/home/rohit/Desktop/CRUD/env/lib/python3.6/site-packages/django/core/handlers/base.py", line 179, in _get_response
    response = wrapped_callback(request, *callback_args, **callback_kwargs)
  File "/home/rohit/Desktop/CRUD/env/lib/python3.6/site-packages/django/views/decorators/csrf.py", line 54, in wrapped_view
    return view_func(*args, **kwargs)
  File "/home/rohit/Desktop/CRUD/env/lib/python3.6/site-packages/rest_framework/viewsets.py", line 114, in view
    return self.dispatch(request, *args, **kwargs)
  File "/home/rohit/Desktop/CRUD/env/lib/python3.6/site-packages/rest_framework/views.py", line 505, in dispatch
    response = self.handle_exception(exc)
  File "/home/rohit/Desktop/CRUD/env/lib/python3.6/site-packages/rest_framework/views.py", line 465, in handle_exception
    self.raise_uncaught_exception(exc)
  File "/home/rohit/Desktop/CRUD/env/lib/python3.6/site-packages/rest_framework/views.py", line 476, in raise_uncaught_exception
    raise exc
  File "/home/rohit/Desktop/CRUD/env/lib/python3.6/site-packages/rest_framework/views.py", line 502, in dispatch
    response = handler(request, *args, **kwargs)
  File "/home/rohit/Desktop/CRUD/POLITICS/district/views.py", line 68, in list
    raise serializers.ParseError("Internal Server Error", status.HTTP_500_INTERNAL_SERVER_ERROR)
AttributeError: module 'rest_framework.serializers' has no attribute 'ParseError'
2020-11-13 22:16:42,605 [ERROR] {/home/rohit/Desktop/CRUD/POLITICS/district/views.py:68} : Exception occured is = division by zero
2020-11-13 22:16:42,765 [ERROR] {/home/rohit/Desktop/CRUD/env/lib/python3.6/site-packages/django/utils/log.py:230} : Internal Server Error: /district/View_Set/TVS/
Traceback (most recent call last):
  File "/home/rohit/Desktop/CRUD/POLITICS/district/views.py", line 66, in list
    a = 10 / 0
ZeroDivisionError: division by zero

During handling of the above exception, another exception occurred:

Traceback (most recent call last):
  File "/home/rohit/Desktop/CRUD/env/lib/python3.6/site-packages/django/core/handlers/exception.py", line 47, in inner
    response = get_response(request)
  File "/home/rohit/Desktop/CRUD/env/lib/python3.6/site-packages/django/core/handlers/base.py", line 179, in _get_response
    response = wrapped_callback(request, *callback_args, **callback_kwargs)
  File "/home/rohit/Desktop/CRUD/env/lib/python3.6/site-packages/django/views/decorators/csrf.py", line 54, in wrapped_view
    return view_func(*args, **kwargs)
  File "/home/rohit/Desktop/CRUD/env/lib/python3.6/site-packages/rest_framework/viewsets.py", line 114, in view
    return self.dispatch(request, *args, **kwargs)
  File "/home/rohit/Desktop/CRUD/env/lib/python3.6/site-packages/rest_framework/views.py", line 505, in dispatch
    response = self.handle_exception(exc)
  File "/home/rohit/Desktop/CRUD/env/lib/python3.6/site-packages/rest_framework/views.py", line 465, in handle_exception
    self.raise_uncaught_exception(exc)
  File "/home/rohit/Desktop/CRUD/env/lib/python3.6/site-packages/rest_framework/views.py", line 476, in raise_uncaught_exception
    raise exc
  File "/home/rohit/Desktop/CRUD/env/lib/python3.6/site-packages/rest_framework/views.py", line 502, in dispatch
    response = handler(request, *args, **kwargs)
  File "/home/rohit/Desktop/CRUD/POLITICS/district/views.py", line 69, in list
    raise serializers.ParseError("Internal Server Error", status.HTTP_500_INTERNAL_SERVER_ERROR)
AttributeError: module 'rest_framework.serializers' has no attribute 'ParseError'
2020-11-13 22:17:08,328 [ERROR] {/home/rohit/Desktop/CRUD/POLITICS/district/views.py:68} : Exception occured is = division by zero
2020-11-13 22:17:26,875 [ERROR] {/home/rohit/Desktop/CRUD/POLITICS/district/views.py:68} : Exception occured is = division by zero
2020-11-14 12:21:42,603 [ERROR] {/home/rohit/Desktop/CRUD/POLITICS/district/views.py:69} : Exception occured is = 'QuerySet' object has no attribute 'queries'
2020-11-14 12:22:05,053 [ERROR] {/home/rohit/Desktop/CRUD/POLITICS/district/views.py:69} : Exception occured is = 'QuerySet' object has no attribute 'queries'
2020-11-14 12:24:12,752 [ERROR] {/home/rohit/Desktop/CRUD/POLITICS/district/views.py:69} : Exception occured is = all() got an unexpected keyword argument 'id'
2020-11-14 12:28:55,716 [ERROR] {/home/rohit/Desktop/CRUD/POLITICS/district/views.py:69} : Exception occured is = 'Manager' object has no attribute 'include'
2020-11-16 21:29:54,192 [ERROR] {/home/rohit/Desktop/CRUD/POLITICS/district/views.py:75} : Exception occured is = 'QuerySet' object has no attribute 'value'
2020-11-16 21:30:25,385 [ERROR] {/home/rohit/Desktop/CRUD/POLITICS/district/views.py:75} : Exception occured is = 'QuerySet' object has no attribute 'value'
2020-11-16 21:30:27,425 [ERROR] {/home/rohit/Desktop/CRUD/POLITICS/district/views.py:75} : Exception occured is = 'QuerySet' object has no attribute 'value'
2020-11-16 21:31:57,137 [ERROR] {/home/rohit/Desktop/CRUD/POLITICS/district/views.py:75} : Exception occured is = 'QuerySet' object has no attribute 'value_list'
2020-11-16 21:31:59,258 [ERROR] {/home/rohit/Desktop/CRUD/POLITICS/district/views.py:75} : Exception occured is = 'QuerySet' object has no attribute 'value_list'
2020-11-16 21:32:13,998 [ERROR] {/home/rohit/Desktop/CRUD/POLITICS/district/views.py:75} : Exception occured is = 'Manager' object has no attribute 'value_list'
2020-11-16 21:39:55,553 [ERROR] {/home/rohit/Desktop/CRUD/POLITICS/district/views.py:75} : Exception occured is = QuerySet.annotate() received non-expression(s): True.
2020-11-16 21:43:00,602 [ERROR] {/home/rohit/Desktop/CRUD/POLITICS/district/views.py:80} : Exception occured is = 'dict' object has no attribute 'id'
2020-11-16 21:43:52,314 [ERROR] {/home/rohit/Desktop/CRUD/POLITICS/district/views.py:81} : Exception occured is = name 'language_ids' is not defined
2020-11-16 21:45:52,837 [ERROR] {/home/rohit/Desktop/CRUD/POLITICS/district/views.py:80} : Exception occured is = 'builtin_function_or_method' object has no attribute 'obj'
2020-11-16 21:49:54,795 [ERROR] {/home/rohit/Desktop/CRUD/POLITICS/district/views.py:82} : Exception occured is = 'Framework' object has no attribute 'labguage_id'
2020-11-18 16:18:12,798 [ERROR] {/home/rohit/Desktop/CRUD/POLITICS/district/views.py:87} : Exception occured is = 'Language' object is not iterable
2020-11-18 16:18:36,896 [ERROR] {/home/rohit/Desktop/CRUD/POLITICS/district/views.py:87} : Exception occured is = 'RelatedManager' object is not iterable
2020-11-18 16:46:18,060 [ERROR] {/home/rohit/Desktop/CRUD/POLITICS/district/views.py:90} : Exception occured is = Cannot resolve keyword 'framework' into field. Choices are: id, lan_frame, name
2020-11-18 19:44:22,189 [ERROR] {/home/rohit/Desktop/CRUD/POLITICS/district/views.py:72} : Exception occured is = Invalid field name(s) given in select_related: 'lan_frame'. Choices are: (none)
2020-11-18 19:45:18,412 [ERROR] {/home/rohit/Desktop/CRUD/POLITICS/district/views.py:72} : Exception occured is = Invalid field name(s) given in select_related: 'lan_frame'. Choices are: (none)
2020-11-18 19:45:19,717 [ERROR] {/home/rohit/Desktop/CRUD/POLITICS/district/views.py:72} : Exception occured is = Invalid field name(s) given in select_related: 'lan_frame'. Choices are: (none)
2020-11-18 19:46:08,638 [ERROR] {/home/rohit/Desktop/CRUD/POLITICS/district/views.py:72} : Exception occured is = Invalid field name(s) given in select_related: 'lan_frame'. Choices are: (none)
2020-11-18 19:46:39,975 [ERROR] {/home/rohit/Desktop/CRUD/POLITICS/district/views.py:72} : Exception occured is = Invalid field name(s) given in select_related: 'lan_frame'. Choices are: (none)
2020-11-18 19:47:49,008 [ERROR] {/home/rohit/Desktop/CRUD/POLITICS/district/views.py:72} : Exception occured is = Invalid field name(s) given in select_related: 'lan_frame'. Choices are: (none)
2020-11-19 11:22:25,917 [ERROR] {/home/rohit/Desktop/CRUD/POLITICS/district/views.py:74} : Exception occured is = 'Language' object has no attribute 'framework_set'
2020-11-19 11:36:38,402 [ERROR] {/home/rohit/Desktop/CRUD/POLITICS/district/views.py:76} : Exception occured is = Invalid field name(s) given in select_related: 'lan_frame'. Choices are: (none)
2020-11-19 11:36:58,361 [ERROR] {/home/rohit/Desktop/CRUD/POLITICS/district/views.py:76} : Exception occured is = Invalid field name(s) given in select_related: 'lan_frame'. Choices are: (none)
2020-11-19 11:37:07,548 [ERROR] {/home/rohit/Desktop/CRUD/POLITICS/district/views.py:76} : Exception occured is = Invalid field name(s) given in select_related: 'lan_frame'. Choices are: (none)
2020-11-19 11:37:43,518 [ERROR] {/home/rohit/Desktop/CRUD/POLITICS/district/views.py:76} : Exception occured is = Invalid field name(s) given in select_related: 'lan_frame'. Choices are: (none)
2020-11-19 11:59:45,105 [ERROR] {/home/rohit/Desktop/CRUD/POLITICS/district/views.py:76} : Exception occured is = 'function' object has no attribute 'all'
2020-11-19 12:00:14,904 [ERROR] {/home/rohit/Desktop/CRUD/POLITICS/district/views.py:76} : Exception occured is = 'function' object has no attribute 'get'
2020-11-19 12:03:54,742 [ERROR] {/home/rohit/Desktop/CRUD/POLITICS/district/views.py:76} : Exception occured is = 'Language' object has no attribute 'frameworks_set'
2020-11-19 16:30:53,717 [ERROR] {/home/rohit/Desktop/CRUD/POLITICS/district/views.py:81} : Exception occured is = Cannot find 'framework_set' on Language object, 'framework_set' is an invalid parameter to prefetch_related()
2020-11-20 12:36:43,654 [ERROR] {/home/rohit/Desktop/CRUD/POLITICS/district/views.py:86} : Exception occured is = (1062, "Duplicate entry 'model1_name' for key 'name'")
2020-11-20 12:40:29,439 [ERROR] {/home/rohit/Desktop/CRUD/POLITICS/district/views.py:98} : Exception occured is = Cannot assign "1": "Model3.model1" must be a "Model1" instance.
2020-11-23 20:29:38,579 [ERROR] {/home/rohit/Desktop/CRUD/env/lib/python3.6/site-packages/django/utils/log.py:230} : Internal Server Error: /district/View_Set/TVS/
Traceback (most recent call last):
  File "/home/rohit/Desktop/CRUD/env/lib/python3.6/site-packages/django/core/handlers/exception.py", line 47, in inner
    response = get_response(request)
  File "/home/rohit/Desktop/CRUD/env/lib/python3.6/site-packages/django/core/handlers/base.py", line 179, in _get_response
    response = wrapped_callback(request, *callback_args, **callback_kwargs)
  File "/home/rohit/Desktop/CRUD/env/lib/python3.6/site-packages/django/views/decorators/csrf.py", line 54, in wrapped_view
    return view_func(*args, **kwargs)
  File "/home/rohit/Desktop/CRUD/env/lib/python3.6/site-packages/rest_framework/viewsets.py", line 114, in view
    return self.dispatch(request, *args, **kwargs)
  File "/home/rohit/Desktop/CRUD/env/lib/python3.6/site-packages/rest_framework/views.py", line 507, in dispatch
    self.response = self.finalize_response(request, response, *args, **kwargs)
  File "/home/rohit/Desktop/CRUD/env/lib/python3.6/site-packages/rest_framework/views.py", line 422, in finalize_response
    % type(response)
AssertionError: Expected a `Response`, `HttpResponse` or `HttpStreamingResponse` to be returned from the view, but received a `<class 'NoneType'>`
2020-11-23 20:37:17,710 [ERROR] {/home/rohit/Desktop/CRUD/POLITICS/district/views.py:91} : Exception occured is = 'Framework' object does not support indexing
2020-11-23 20:40:28,522 [ERROR] {/home/rohit/Desktop/CRUD/POLITICS/district/views.py:89} : Exception occured is = 'Framework' object has no attribute 'framework'
2020-11-25 22:25:00,559 [ERROR] {/home/rohit/Desktop/CRUD/POLITICS/district/views.py:91} : Exception occured is = Cannot resolve keyword 'framework' into field. Choices are: id, lan_frame, name
2020-11-26 12:22:20,883 [ERROR] {/home/rohit/Desktop/CRUD/POLITICS/district/views.py:92} : Exception occured is = Cannot resolve keyword 'framework' into field. Choices are: id, lan_frame, name
2020-11-26 12:25:42,224 [ERROR] {/home/rohit/Desktop/CRUD/POLITICS/district/views.py:92} : Exception occured is = Cannot resolve keyword 'framework' into field. Choices are: id, lan_frame, name
2020-11-26 12:26:16,170 [ERROR] {/home/rohit/Desktop/CRUD/POLITICS/district/views.py:92} : Exception occured is = Cannot resolve keyword 'framework' into field. Choices are: id, lan_frame, name
2020-11-26 17:21:40,129 [ERROR] {/home/rohit/Desktop/CRUD/POLITICS/district/views.py:94} : Exception occured is = 'Language' object has no attribute 'framework'
2020-11-26 17:23:38,367 [ERROR] {/home/rohit/Desktop/CRUD/POLITICS/district/views.py:94} : Exception occured is = Cannot resolve keyword 'framework' into field. Choices are: id, lan_frame, name
2020-11-26 17:23:53,083 [ERROR] {/home/rohit/Desktop/CRUD/POLITICS/district/views.py:94} : Exception occured is = Cannot resolve keyword 'framework' into field. Choices are: id, lan_frame, name
2020-11-26 17:24:37,660 [ERROR] {/home/rohit/Desktop/CRUD/POLITICS/district/views.py:94} : Exception occured is = 'Language' object has no attribute 'framework'
2020-11-27 23:01:32,404 [ERROR] {/home/rohit/Desktop/CRUD/env/lib/python3.6/site-packages/django/utils/log.py:230} : Internal Server Error: /district/View_Set/TVS/
Traceback (most recent call last):
  File "/home/rohit/Desktop/CRUD/env/lib/python3.6/site-packages/django/core/handlers/exception.py", line 47, in inner
    response = get_response(request)
  File "/home/rohit/Desktop/CRUD/env/lib/python3.6/site-packages/django/core/handlers/base.py", line 179, in _get_response
    response = wrapped_callback(request, *callback_args, **callback_kwargs)
  File "/home/rohit/Desktop/CRUD/env/lib/python3.6/site-packages/django/views/decorators/csrf.py", line 54, in wrapped_view
    return view_func(*args, **kwargs)
  File "/home/rohit/Desktop/CRUD/env/lib/python3.6/site-packages/rest_framework/viewsets.py", line 114, in view
    return self.dispatch(request, *args, **kwargs)
  File "/home/rohit/Desktop/CRUD/env/lib/python3.6/site-packages/rest_framework/views.py", line 507, in dispatch
    self.response = self.finalize_response(request, response, *args, **kwargs)
  File "/home/rohit/Desktop/CRUD/env/lib/python3.6/site-packages/rest_framework/views.py", line 422, in finalize_response
    % type(response)
AssertionError: Expected a `Response`, `HttpResponse` or `HttpStreamingResponse` to be returned from the view, but received a `<class 'NoneType'>`
2020-11-28 15:20:40,567 [ERROR] {/home/rohit/Desktop/CRUD/env/lib/python3.6/site-packages/django/utils/log.py:230} : Internal Server Error: /district/View_Set/TVS/
Traceback (most recent call last):
  File "/home/rohit/Desktop/CRUD/env/lib/python3.6/site-packages/django/core/handlers/exception.py", line 47, in inner
    response = get_response(request)
  File "/home/rohit/Desktop/CRUD/env/lib/python3.6/site-packages/django/core/handlers/base.py", line 179, in _get_response
    response = wrapped_callback(request, *callback_args, **callback_kwargs)
  File "/home/rohit/Desktop/CRUD/env/lib/python3.6/site-packages/django/views/decorators/csrf.py", line 54, in wrapped_view
    return view_func(*args, **kwargs)
  File "/home/rohit/Desktop/CRUD/env/lib/python3.6/site-packages/rest_framework/viewsets.py", line 114, in view
    return self.dispatch(request, *args, **kwargs)
  File "/home/rohit/Desktop/CRUD/env/lib/python3.6/site-packages/rest_framework/views.py", line 507, in dispatch
    self.response = self.finalize_response(request, response, *args, **kwargs)
  File "/home/rohit/Desktop/CRUD/env/lib/python3.6/site-packages/rest_framework/views.py", line 422, in finalize_response
    % type(response)
AssertionError: Expected a `Response`, `HttpResponse` or `HttpStreamingResponse` to be returned from the view, but received a `<class 'NoneType'>`
2020-11-28 19:07:33,319 [ERROR] {/home/rohit/Desktop/CRUD/env/lib/python3.6/site-packages/django/utils/log.py:230} : Internal Server Error: /district/View_Set/TVS/
Traceback (most recent call last):
  File "/home/rohit/Desktop/CRUD/env/lib/python3.6/site-packages/django/core/handlers/exception.py", line 47, in inner
    response = get_response(request)
  File "/home/rohit/Desktop/CRUD/env/lib/python3.6/site-packages/django/core/handlers/base.py", line 179, in _get_response
    response = wrapped_callback(request, *callback_args, **callback_kwargs)
  File "/home/rohit/Desktop/CRUD/env/lib/python3.6/site-packages/django/views/decorators/csrf.py", line 54, in wrapped_view
    return view_func(*args, **kwargs)
  File "/home/rohit/Desktop/CRUD/env/lib/python3.6/site-packages/rest_framework/viewsets.py", line 114, in view
    return self.dispatch(request, *args, **kwargs)
  File "/home/rohit/Desktop/CRUD/env/lib/python3.6/site-packages/rest_framework/views.py", line 505, in dispatch
    response = self.handle_exception(exc)
  File "/home/rohit/Desktop/CRUD/env/lib/python3.6/site-packages/rest_framework/views.py", line 465, in handle_exception
    self.raise_uncaught_exception(exc)
  File "/home/rohit/Desktop/CRUD/env/lib/python3.6/site-packages/rest_framework/views.py", line 476, in raise_uncaught_exception
    raise exc
  File "/home/rohit/Desktop/CRUD/env/lib/python3.6/site-packages/rest_framework/views.py", line 502, in dispatch
    response = handler(request, *args, **kwargs)
  File "/home/rohit/Desktop/CRUD/POLITICS/district/decorator.py", line 36, in __call__
    return self.view_function(*args, **kwargs)
TypeError: list() missing 1 required positional argument: 'request'
2020-11-28 19:08:16,786 [ERROR] {/home/rohit/Desktop/CRUD/env/lib/python3.6/site-packages/django/utils/log.py:230} : Internal Server Error: /district/View_Set/TVS/
Traceback (most recent call last):
  File "/home/rohit/Desktop/CRUD/env/lib/python3.6/site-packages/django/core/handlers/exception.py", line 47, in inner
    response = get_response(request)
  File "/home/rohit/Desktop/CRUD/env/lib/python3.6/site-packages/django/core/handlers/base.py", line 179, in _get_response
    response = wrapped_callback(request, *callback_args, **callback_kwargs)
  File "/home/rohit/Desktop/CRUD/env/lib/python3.6/site-packages/django/views/decorators/csrf.py", line 54, in wrapped_view
    return view_func(*args, **kwargs)
  File "/home/rohit/Desktop/CRUD/env/lib/python3.6/site-packages/rest_framework/viewsets.py", line 114, in view
    return self.dispatch(request, *args, **kwargs)
  File "/home/rohit/Desktop/CRUD/env/lib/python3.6/site-packages/rest_framework/views.py", line 505, in dispatch
    response = self.handle_exception(exc)
  File "/home/rohit/Desktop/CRUD/env/lib/python3.6/site-packages/rest_framework/views.py", line 465, in handle_exception
    self.raise_uncaught_exception(exc)
  File "/home/rohit/Desktop/CRUD/env/lib/python3.6/site-packages/rest_framework/views.py", line 476, in raise_uncaught_exception
    raise exc
  File "/home/rohit/Desktop/CRUD/env/lib/python3.6/site-packages/rest_framework/views.py", line 502, in dispatch
    response = handler(request, *args, **kwargs)
  File "/home/rohit/Desktop/CRUD/POLITICS/district/decorator.py", line 36, in __call__
    return self.view_function(request, *args, **kwargs)
TypeError: list() missing 1 required positional argument: 'request'
2020-11-28 19:11:07,843 [ERROR] {/home/rohit/Desktop/CRUD/env/lib/python3.6/site-packages/django/utils/log.py:230} : Internal Server Error: /district/View_Set/TVS/
Traceback (most recent call last):
  File "/home/rohit/Desktop/CRUD/env/lib/python3.6/site-packages/django/core/handlers/exception.py", line 47, in inner
    response = get_response(request)
  File "/home/rohit/Desktop/CRUD/env/lib/python3.6/site-packages/django/core/handlers/base.py", line 179, in _get_response
    response = wrapped_callback(request, *callback_args, **callback_kwargs)
  File "/home/rohit/Desktop/CRUD/env/lib/python3.6/site-packages/django/views/decorators/csrf.py", line 54, in wrapped_view
    return view_func(*args, **kwargs)
  File "/home/rohit/Desktop/CRUD/env/lib/python3.6/site-packages/rest_framework/viewsets.py", line 114, in view
    return self.dispatch(request, *args, **kwargs)
  File "/home/rohit/Desktop/CRUD/env/lib/python3.6/site-packages/rest_framework/views.py", line 505, in dispatch
    response = self.handle_exception(exc)
  File "/home/rohit/Desktop/CRUD/env/lib/python3.6/site-packages/rest_framework/views.py", line 465, in handle_exception
    self.raise_uncaught_exception(exc)
  File "/home/rohit/Desktop/CRUD/env/lib/python3.6/site-packages/rest_framework/views.py", line 476, in raise_uncaught_exception
    raise exc
  File "/home/rohit/Desktop/CRUD/env/lib/python3.6/site-packages/rest_framework/views.py", line 502, in dispatch
    response = handler(request, *args, **kwargs)
  File "/home/rohit/Desktop/CRUD/POLITICS/district/decorator.py", line 36, in __call__
    self.view_function(request, *args, **kwargs)
TypeError: list() missing 1 required positional argument: 'request'
2020-11-28 19:11:25,382 [ERROR] {/home/rohit/Desktop/CRUD/env/lib/python3.6/site-packages/django/utils/log.py:230} : Internal Server Error: /district/View_Set/TVS/
Traceback (most recent call last):
  File "/home/rohit/Desktop/CRUD/env/lib/python3.6/site-packages/django/core/handlers/exception.py", line 47, in inner
    response = get_response(request)
  File "/home/rohit/Desktop/CRUD/env/lib/python3.6/site-packages/django/core/handlers/base.py", line 179, in _get_response
    response = wrapped_callback(request, *callback_args, **callback_kwargs)
  File "/home/rohit/Desktop/CRUD/env/lib/python3.6/site-packages/django/views/decorators/csrf.py", line 54, in wrapped_view
    return view_func(*args, **kwargs)
  File "/home/rohit/Desktop/CRUD/env/lib/python3.6/site-packages/rest_framework/viewsets.py", line 114, in view
    return self.dispatch(request, *args, **kwargs)
  File "/home/rohit/Desktop/CRUD/env/lib/python3.6/site-packages/rest_framework/views.py", line 507, in dispatch
    self.response = self.finalize_response(request, response, *args, **kwargs)
  File "/home/rohit/Desktop/CRUD/env/lib/python3.6/site-packages/rest_framework/views.py", line 422, in finalize_response
    % type(response)
AssertionError: Expected a `Response`, `HttpResponse` or `HttpStreamingResponse` to be returned from the view, but received a `<class 'NoneType'>`
2020-11-30 20:23:53,184 [ERROR] {/home/rohit/Desktop/CRUD/env/lib/python3.6/site-packages/django/utils/log.py:230} : Internal Server Error: /user/login/
Traceback (most recent call last):
  File "/home/rohit/Desktop/CRUD/env/lib/python3.6/site-packages/django/core/handlers/exception.py", line 47, in inner
    response = get_response(request)
  File "/home/rohit/Desktop/CRUD/env/lib/python3.6/site-packages/django/core/handlers/base.py", line 179, in _get_response
    response = wrapped_callback(request, *callback_args, **callback_kwargs)
  File "/home/rohit/Desktop/CRUD/env/lib/python3.6/site-packages/django/views/decorators/csrf.py", line 54, in wrapped_view
    return view_func(*args, **kwargs)
  File "/home/rohit/Desktop/CRUD/env/lib/python3.6/site-packages/django/views/generic/base.py", line 70, in view
    return self.dispatch(request, *args, **kwargs)
  File "/home/rohit/Desktop/CRUD/env/lib/python3.6/site-packages/rest_framework/views.py", line 505, in dispatch
    response = self.handle_exception(exc)
  File "/home/rohit/Desktop/CRUD/env/lib/python3.6/site-packages/rest_framework/views.py", line 465, in handle_exception
    self.raise_uncaught_exception(exc)
  File "/home/rohit/Desktop/CRUD/env/lib/python3.6/site-packages/rest_framework/views.py", line 476, in raise_uncaught_exception
    raise exc
  File "/home/rohit/Desktop/CRUD/env/lib/python3.6/site-packages/rest_framework/views.py", line 502, in dispatch
    response = handler(request, *args, **kwargs)
  File "/home/rohit/Desktop/CRUD/POLITICS/user_info/views.py", line 48, in post
    user = serializer.validated_data['user']
KeyError: 'user'
2020-11-30 20:25:54,362 [ERROR] {/home/rohit/Desktop/CRUD/env/lib/python3.6/site-packages/django/utils/log.py:230} : Internal Server Error: /user/login/
Traceback (most recent call last):
  File "/home/rohit/Desktop/CRUD/env/lib/python3.6/site-packages/django/core/handlers/exception.py", line 47, in inner
    response = get_response(request)
  File "/home/rohit/Desktop/CRUD/env/lib/python3.6/site-packages/django/core/handlers/base.py", line 179, in _get_response
    response = wrapped_callback(request, *callback_args, **callback_kwargs)
  File "/home/rohit/Desktop/CRUD/env/lib/python3.6/site-packages/django/views/decorators/csrf.py", line 54, in wrapped_view
    return view_func(*args, **kwargs)
  File "/home/rohit/Desktop/CRUD/env/lib/python3.6/site-packages/django/views/generic/base.py", line 70, in view
    return self.dispatch(request, *args, **kwargs)
  File "/home/rohit/Desktop/CRUD/env/lib/python3.6/site-packages/rest_framework/views.py", line 505, in dispatch
    response = self.handle_exception(exc)
  File "/home/rohit/Desktop/CRUD/env/lib/python3.6/site-packages/rest_framework/views.py", line 465, in handle_exception
    self.raise_uncaught_exception(exc)
  File "/home/rohit/Desktop/CRUD/env/lib/python3.6/site-packages/rest_framework/views.py", line 476, in raise_uncaught_exception
    raise exc
  File "/home/rohit/Desktop/CRUD/env/lib/python3.6/site-packages/rest_framework/views.py", line 502, in dispatch
    response = handler(request, *args, **kwargs)
  File "/home/rohit/Desktop/CRUD/POLITICS/user_info/views.py", line 46, in post
    if serializer.is_valid():
  File "/home/rohit/Desktop/CRUD/env/lib/python3.6/site-packages/rest_framework/serializers.py", line 234, in is_valid
    self._validated_data = self.run_validation(self.initial_data)
  File "/home/rohit/Desktop/CRUD/env/lib/python3.6/site-packages/rest_framework/serializers.py", line 433, in run_validation
    value = self.to_internal_value(data)
  File "/home/rohit/Desktop/CRUD/env/lib/python3.6/site-packages/rest_framework/serializers.py", line 486, in to_internal_value
    for field in fields:
  File "/home/rohit/Desktop/CRUD/env/lib/python3.6/site-packages/rest_framework/serializers.py", line 369, in _writable_fields
    for field in self.fields.values():
  File "/home/rohit/Desktop/CRUD/env/lib/python3.6/site-packages/django/utils/functional.py", line 48, in __get__
    res = instance.__dict__[self.name] = self.func(instance)
  File "/home/rohit/Desktop/CRUD/env/lib/python3.6/site-packages/rest_framework/serializers.py", line 363, in fields
    for key, value in self.get_fields().items():
  File "/home/rohit/Desktop/CRUD/env/lib/python3.6/site-packages/rest_framework/serializers.py", line 1015, in get_fields
    serializer_class=self.__class__.__name__
AssertionError: Class LoginSerializer missing "Meta" attribute
2020-11-30 20:33:40,980 [ERROR] {/home/rohit/Desktop/CRUD/env/lib/python3.6/site-packages/django/utils/log.py:230} : Internal Server Error: /user/login/
Traceback (most recent call last):
  File "/home/rohit/Desktop/CRUD/env/lib/python3.6/site-packages/django/core/handlers/exception.py", line 47, in inner
    response = get_response(request)
  File "/home/rohit/Desktop/CRUD/env/lib/python3.6/site-packages/django/core/handlers/base.py", line 179, in _get_response
    response = wrapped_callback(request, *callback_args, **callback_kwargs)
  File "/home/rohit/Desktop/CRUD/env/lib/python3.6/site-packages/django/views/decorators/csrf.py", line 54, in wrapped_view
    return view_func(*args, **kwargs)
  File "/home/rohit/Desktop/CRUD/env/lib/python3.6/site-packages/django/views/generic/base.py", line 70, in view
    return self.dispatch(request, *args, **kwargs)
  File "/home/rohit/Desktop/CRUD/env/lib/python3.6/site-packages/rest_framework/views.py", line 505, in dispatch
    response = self.handle_exception(exc)
  File "/home/rohit/Desktop/CRUD/env/lib/python3.6/site-packages/rest_framework/views.py", line 465, in handle_exception
    self.raise_uncaught_exception(exc)
  File "/home/rohit/Desktop/CRUD/env/lib/python3.6/site-packages/rest_framework/views.py", line 476, in raise_uncaught_exception
    raise exc
  File "/home/rohit/Desktop/CRUD/env/lib/python3.6/site-packages/rest_framework/views.py", line 502, in dispatch
    response = handler(request, *args, **kwargs)
  File "/home/rohit/Desktop/CRUD/POLITICS/user_info/views.py", line 46, in post
    if serializer.is_valid():
  File "/home/rohit/Desktop/CRUD/env/lib/python3.6/site-packages/rest_framework/serializers.py", line 234, in is_valid
    self._validated_data = self.run_validation(self.initial_data)
  File "/home/rohit/Desktop/CRUD/env/lib/python3.6/site-packages/rest_framework/serializers.py", line 433, in run_validation
    value = self.to_internal_value(data)
  File "/home/rohit/Desktop/CRUD/env/lib/python3.6/site-packages/rest_framework/serializers.py", line 486, in to_internal_value
    for field in fields:
  File "/home/rohit/Desktop/CRUD/env/lib/python3.6/site-packages/rest_framework/serializers.py", line 369, in _writable_fields
    for field in self.fields.values():
  File "/home/rohit/Desktop/CRUD/env/lib/python3.6/site-packages/django/utils/functional.py", line 48, in __get__
    res = instance.__dict__[self.name] = self.func(instance)
  File "/home/rohit/Desktop/CRUD/env/lib/python3.6/site-packages/rest_framework/serializers.py", line 363, in fields
    for key, value in self.get_fields().items():
  File "/home/rohit/Desktop/CRUD/env/lib/python3.6/site-packages/rest_framework/serializers.py", line 1038, in get_fields
    field_names = self.get_field_names(declared_fields, info)
  File "/home/rohit/Desktop/CRUD/env/lib/python3.6/site-packages/rest_framework/serializers.py", line 1094, in get_field_names
    'Got %s.' % type(fields).__name__
TypeError: The `fields` option must be a list or tuple or "__all__". Got str.
2020-11-30 20:34:02,087 [ERROR] {/home/rohit/Desktop/CRUD/env/lib/python3.6/site-packages/django/utils/log.py:230} : Internal Server Error: /user/login/
Traceback (most recent call last):
  File "/home/rohit/Desktop/CRUD/env/lib/python3.6/site-packages/django/core/handlers/exception.py", line 47, in inner
    response = get_response(request)
  File "/home/rohit/Desktop/CRUD/env/lib/python3.6/site-packages/django/core/handlers/base.py", line 179, in _get_response
    response = wrapped_callback(request, *callback_args, **callback_kwargs)
  File "/home/rohit/Desktop/CRUD/env/lib/python3.6/site-packages/django/views/decorators/csrf.py", line 54, in wrapped_view
    return view_func(*args, **kwargs)
  File "/home/rohit/Desktop/CRUD/env/lib/python3.6/site-packages/django/views/generic/base.py", line 70, in view
    return self.dispatch(request, *args, **kwargs)
  File "/home/rohit/Desktop/CRUD/env/lib/python3.6/site-packages/rest_framework/views.py", line 505, in dispatch
    response = self.handle_exception(exc)
  File "/home/rohit/Desktop/CRUD/env/lib/python3.6/site-packages/rest_framework/views.py", line 465, in handle_exception
    self.raise_uncaught_exception(exc)
  File "/home/rohit/Desktop/CRUD/env/lib/python3.6/site-packages/rest_framework/views.py", line 476, in raise_uncaught_exception
    raise exc
  File "/home/rohit/Desktop/CRUD/env/lib/python3.6/site-packages/rest_framework/views.py", line 502, in dispatch
    response = handler(request, *args, **kwargs)
  File "/home/rohit/Desktop/CRUD/POLITICS/user_info/views.py", line 46, in post
    if serializer.is_valid():
  File "/home/rohit/Desktop/CRUD/env/lib/python3.6/site-packages/rest_framework/serializers.py", line 234, in is_valid
    self._validated_data = self.run_validation(self.initial_data)
  File "/home/rohit/Desktop/CRUD/env/lib/python3.6/site-packages/rest_framework/serializers.py", line 436, in run_validation
    value = self.validate(value)
  File "/home/rohit/Desktop/CRUD/POLITICS/user_info/serializers.py", line 31, in validate
    user = User.objects.get(username=username, password=password)
  File "/home/rohit/Desktop/CRUD/env/lib/python3.6/site-packages/django/db/models/manager.py", line 85, in manager_method
    return getattr(self.get_queryset(), name)(*args, **kwargs)
  File "/home/rohit/Desktop/CRUD/env/lib/python3.6/site-packages/django/db/models/query.py", line 431, in get
    self.model._meta.object_name
django.contrib.auth.models.User.DoesNotExist: User matching query does not exist.
2020-11-30 20:34:04,048 [ERROR] {/home/rohit/Desktop/CRUD/env/lib/python3.6/site-packages/django/utils/log.py:230} : Internal Server Error: /user/login/
Traceback (most recent call last):
  File "/home/rohit/Desktop/CRUD/env/lib/python3.6/site-packages/django/core/handlers/exception.py", line 47, in inner
    response = get_response(request)
  File "/home/rohit/Desktop/CRUD/env/lib/python3.6/site-packages/django/core/handlers/base.py", line 179, in _get_response
    response = wrapped_callback(request, *callback_args, **callback_kwargs)
  File "/home/rohit/Desktop/CRUD/env/lib/python3.6/site-packages/django/views/decorators/csrf.py", line 54, in wrapped_view
    return view_func(*args, **kwargs)
  File "/home/rohit/Desktop/CRUD/env/lib/python3.6/site-packages/django/views/generic/base.py", line 70, in view
    return self.dispatch(request, *args, **kwargs)
  File "/home/rohit/Desktop/CRUD/env/lib/python3.6/site-packages/rest_framework/views.py", line 505, in dispatch
    response = self.handle_exception(exc)
  File "/home/rohit/Desktop/CRUD/env/lib/python3.6/site-packages/rest_framework/views.py", line 465, in handle_exception
    self.raise_uncaught_exception(exc)
  File "/home/rohit/Desktop/CRUD/env/lib/python3.6/site-packages/rest_framework/views.py", line 476, in raise_uncaught_exception
    raise exc
  File "/home/rohit/Desktop/CRUD/env/lib/python3.6/site-packages/rest_framework/views.py", line 502, in dispatch
    response = handler(request, *args, **kwargs)
  File "/home/rohit/Desktop/CRUD/POLITICS/user_info/views.py", line 46, in post
    if serializer.is_valid():
  File "/home/rohit/Desktop/CRUD/env/lib/python3.6/site-packages/rest_framework/serializers.py", line 234, in is_valid
    self._validated_data = self.run_validation(self.initial_data)
  File "/home/rohit/Desktop/CRUD/env/lib/python3.6/site-packages/rest_framework/serializers.py", line 436, in run_validation
    value = self.validate(value)
  File "/home/rohit/Desktop/CRUD/POLITICS/user_info/serializers.py", line 31, in validate
    user = User.objects.get(username=username, password=password)
  File "/home/rohit/Desktop/CRUD/env/lib/python3.6/site-packages/django/db/models/manager.py", line 85, in manager_method
    return getattr(self.get_queryset(), name)(*args, **kwargs)
  File "/home/rohit/Desktop/CRUD/env/lib/python3.6/site-packages/django/db/models/query.py", line 431, in get
    self.model._meta.object_name
django.contrib.auth.models.User.DoesNotExist: User matching query does not exist.
2020-11-30 20:51:00,034 [ERROR] {/home/rohit/Desktop/CRUD/env/lib/python3.6/site-packages/django/utils/log.py:230} : Internal Server Error: /user/login/
Traceback (most recent call last):
  File "/home/rohit/Desktop/CRUD/env/lib/python3.6/site-packages/django/core/handlers/exception.py", line 47, in inner
    response = get_response(request)
  File "/home/rohit/Desktop/CRUD/env/lib/python3.6/site-packages/django/core/handlers/base.py", line 179, in _get_response
    response = wrapped_callback(request, *callback_args, **callback_kwargs)
  File "/home/rohit/Desktop/CRUD/env/lib/python3.6/site-packages/django/views/decorators/csrf.py", line 54, in wrapped_view
    return view_func(*args, **kwargs)
  File "/home/rohit/Desktop/CRUD/env/lib/python3.6/site-packages/django/views/generic/base.py", line 70, in view
    return self.dispatch(request, *args, **kwargs)
  File "/home/rohit/Desktop/CRUD/env/lib/python3.6/site-packages/rest_framework/views.py", line 505, in dispatch
    response = self.handle_exception(exc)
  File "/home/rohit/Desktop/CRUD/env/lib/python3.6/site-packages/rest_framework/views.py", line 465, in handle_exception
    self.raise_uncaught_exception(exc)
  File "/home/rohit/Desktop/CRUD/env/lib/python3.6/site-packages/rest_framework/views.py", line 476, in raise_uncaught_exception
    raise exc
  File "/home/rohit/Desktop/CRUD/env/lib/python3.6/site-packages/rest_framework/views.py", line 502, in dispatch
    response = handler(request, *args, **kwargs)
  File "/home/rohit/Desktop/CRUD/POLITICS/user_info/views.py", line 46, in post
    if serializer.is_valid():
  File "/home/rohit/Desktop/CRUD/env/lib/python3.6/site-packages/rest_framework/serializers.py", line 234, in is_valid
    self._validated_data = self.run_validation(self.initial_data)
  File "/home/rohit/Desktop/CRUD/env/lib/python3.6/site-packages/rest_framework/serializers.py", line 433, in run_validation
    value = self.to_internal_value(data)
  File "/home/rohit/Desktop/CRUD/env/lib/python3.6/site-packages/rest_framework/serializers.py", line 486, in to_internal_value
    for field in fields:
  File "/home/rohit/Desktop/CRUD/env/lib/python3.6/site-packages/rest_framework/serializers.py", line 369, in _writable_fields
    for field in self.fields.values():
  File "/home/rohit/Desktop/CRUD/env/lib/python3.6/site-packages/django/utils/functional.py", line 48, in __get__
    res = instance.__dict__[self.name] = self.func(instance)
  File "/home/rohit/Desktop/CRUD/env/lib/python3.6/site-packages/rest_framework/serializers.py", line 363, in fields
    for key, value in self.get_fields().items():
  File "/home/rohit/Desktop/CRUD/env/lib/python3.6/site-packages/rest_framework/serializers.py", line 1038, in get_fields
    field_names = self.get_field_names(declared_fields, info)
  File "/home/rohit/Desktop/CRUD/env/lib/python3.6/site-packages/rest_framework/serializers.py", line 1139, in get_field_names
    serializer_class=self.__class__.__name__
AssertionError: The field 'username' was declared on serializer LoginSerializer, but has not been included in the 'fields' option.
2020-11-30 20:59:21,976 [ERROR] {/home/rohit/Desktop/CRUD/env/lib/python3.6/site-packages/django/utils/log.py:230} : Internal Server Error: /user/login/
Traceback (most recent call last):
  File "/home/rohit/Desktop/CRUD/env/lib/python3.6/site-packages/django/core/handlers/exception.py", line 47, in inner
    response = get_response(request)
  File "/home/rohit/Desktop/CRUD/env/lib/python3.6/site-packages/django/core/handlers/base.py", line 179, in _get_response
    response = wrapped_callback(request, *callback_args, **callback_kwargs)
  File "/home/rohit/Desktop/CRUD/env/lib/python3.6/site-packages/django/views/decorators/csrf.py", line 54, in wrapped_view
    return view_func(*args, **kwargs)
  File "/home/rohit/Desktop/CRUD/env/lib/python3.6/site-packages/django/views/generic/base.py", line 70, in view
    return self.dispatch(request, *args, **kwargs)
  File "/home/rohit/Desktop/CRUD/env/lib/python3.6/site-packages/rest_framework/views.py", line 505, in dispatch
    response = self.handle_exception(exc)
  File "/home/rohit/Desktop/CRUD/env/lib/python3.6/site-packages/rest_framework/views.py", line 465, in handle_exception
    self.raise_uncaught_exception(exc)
  File "/home/rohit/Desktop/CRUD/env/lib/python3.6/site-packages/rest_framework/views.py", line 476, in raise_uncaught_exception
    raise exc
  File "/home/rohit/Desktop/CRUD/env/lib/python3.6/site-packages/rest_framework/views.py", line 502, in dispatch
    response = handler(request, *args, **kwargs)
  File "/home/rohit/Desktop/CRUD/POLITICS/user_info/views.py", line 46, in post
    if serializer.is_valid():
  File "/home/rohit/Desktop/CRUD/env/lib/python3.6/site-packages/rest_framework/serializers.py", line 234, in is_valid
    self._validated_data = self.run_validation(self.initial_data)
  File "/home/rohit/Desktop/CRUD/env/lib/python3.6/site-packages/rest_framework/serializers.py", line 436, in run_validation
    value = self.validate(value)
  File "/home/rohit/Desktop/CRUD/POLITICS/user_info/serializers.py", line 31, in validate
    user = User.objects.get(username=username, password=password)
  File "/home/rohit/Desktop/CRUD/env/lib/python3.6/site-packages/django/db/models/manager.py", line 85, in manager_method
    return getattr(self.get_queryset(), name)(*args, **kwargs)
  File "/home/rohit/Desktop/CRUD/env/lib/python3.6/site-packages/django/db/models/query.py", line 431, in get
    self.model._meta.object_name
django.contrib.auth.models.User.DoesNotExist: User matching query does not exist.
2020-11-30 20:59:51,192 [ERROR] {/home/rohit/Desktop/CRUD/env/lib/python3.6/site-packages/django/utils/log.py:230} : Internal Server Error: /user/login/
Traceback (most recent call last):
  File "/home/rohit/Desktop/CRUD/env/lib/python3.6/site-packages/django/core/handlers/exception.py", line 47, in inner
    response = get_response(request)
  File "/home/rohit/Desktop/CRUD/env/lib/python3.6/site-packages/django/core/handlers/base.py", line 179, in _get_response
    response = wrapped_callback(request, *callback_args, **callback_kwargs)
  File "/home/rohit/Desktop/CRUD/env/lib/python3.6/site-packages/django/views/decorators/csrf.py", line 54, in wrapped_view
    return view_func(*args, **kwargs)
  File "/home/rohit/Desktop/CRUD/env/lib/python3.6/site-packages/django/views/generic/base.py", line 70, in view
    return self.dispatch(request, *args, **kwargs)
  File "/home/rohit/Desktop/CRUD/env/lib/python3.6/site-packages/rest_framework/views.py", line 505, in dispatch
    response = self.handle_exception(exc)
  File "/home/rohit/Desktop/CRUD/env/lib/python3.6/site-packages/rest_framework/views.py", line 465, in handle_exception
    self.raise_uncaught_exception(exc)
  File "/home/rohit/Desktop/CRUD/env/lib/python3.6/site-packages/rest_framework/views.py", line 476, in raise_uncaught_exception
    raise exc
  File "/home/rohit/Desktop/CRUD/env/lib/python3.6/site-packages/rest_framework/views.py", line 502, in dispatch
    response = handler(request, *args, **kwargs)
  File "/home/rohit/Desktop/CRUD/POLITICS/user_info/views.py", line 48, in post
    user = serializer.validated_data['user']
KeyError: 'user'
2020-11-30 21:00:09,590 [ERROR] {/home/rohit/Desktop/CRUD/env/lib/python3.6/site-packages/django/utils/log.py:230} : Internal Server Error: /user/login/
Traceback (most recent call last):
  File "/home/rohit/Desktop/CRUD/env/lib/python3.6/site-packages/django/core/handlers/exception.py", line 47, in inner
    response = get_response(request)
  File "/home/rohit/Desktop/CRUD/env/lib/python3.6/site-packages/django/core/handlers/base.py", line 179, in _get_response
    response = wrapped_callback(request, *callback_args, **callback_kwargs)
  File "/home/rohit/Desktop/CRUD/env/lib/python3.6/site-packages/django/views/decorators/csrf.py", line 54, in wrapped_view
    return view_func(*args, **kwargs)
  File "/home/rohit/Desktop/CRUD/env/lib/python3.6/site-packages/django/views/generic/base.py", line 70, in view
    return self.dispatch(request, *args, **kwargs)
  File "/home/rohit/Desktop/CRUD/env/lib/python3.6/site-packages/rest_framework/views.py", line 505, in dispatch
    response = self.handle_exception(exc)
  File "/home/rohit/Desktop/CRUD/env/lib/python3.6/site-packages/rest_framework/views.py", line 465, in handle_exception
    self.raise_uncaught_exception(exc)
  File "/home/rohit/Desktop/CRUD/env/lib/python3.6/site-packages/rest_framework/views.py", line 476, in raise_uncaught_exception
    raise exc
  File "/home/rohit/Desktop/CRUD/env/lib/python3.6/site-packages/rest_framework/views.py", line 502, in dispatch
    response = handler(request, *args, **kwargs)
  File "/home/rohit/Desktop/CRUD/POLITICS/user_info/views.py", line 48, in post
    user = serializer.validated_data['user']
KeyError: 'user'
2020-12-01 12:33:08,057 [ERROR] {/home/rohit/Desktop/CRUD/env/lib/python3.6/site-packages/django/utils/log.py:230} : Internal Server Error: /user/UserAction
Traceback (most recent call last):
  File "/home/rohit/Desktop/CRUD/env/lib/python3.6/site-packages/django/core/handlers/exception.py", line 47, in inner
    response = get_response(request)
  File "/home/rohit/Desktop/CRUD/env/lib/python3.6/site-packages/django/utils/deprecation.py", line 113, in __call__
    response = self.process_request(request)
  File "/home/rohit/Desktop/CRUD/env/lib/python3.6/site-packages/django/middleware/common.py", line 54, in process_request
    path = self.get_full_path_with_slash(request)
  File "/home/rohit/Desktop/CRUD/env/lib/python3.6/site-packages/django/middleware/common.py", line 94, in get_full_path_with_slash
    'url': request.get_host() + new_path,
RuntimeError: You called this URL via POST, but the URL doesn't end in a slash and you have APPEND_SLASH set. Django can't redirect to the slash URL while maintaining POST data. Change your form to point to 127.0.0.1:8001/user/UserAction/ (note the trailing slash), or set APPEND_SLASH=False in your Django settings.
2020-12-01 16:16:30,281 [ERROR] {/home/rohit/Desktop/CRUD/env/lib/python3.6/site-packages/django/utils/log.py:230} : Internal Server Error: /district/View_Set/TVS/
Traceback (most recent call last):
  File "/home/rohit/Desktop/CRUD/POLITICS/district/views.py", line 85, in list
    return Response(str(query_set1.query))
AttributeError: 'Language' object has no attribute 'query'

During handling of the above exception, another exception occurred:

Traceback (most recent call last):
  File "/home/rohit/Desktop/CRUD/env/lib/python3.6/site-packages/django/core/handlers/exception.py", line 47, in inner
    response = get_response(request)
  File "/home/rohit/Desktop/CRUD/env/lib/python3.6/site-packages/django/core/handlers/base.py", line 179, in _get_response
    response = wrapped_callback(request, *callback_args, **callback_kwargs)
  File "/home/rohit/Desktop/CRUD/env/lib/python3.6/site-packages/django/views/decorators/csrf.py", line 54, in wrapped_view
    return view_func(*args, **kwargs)
  File "/home/rohit/Desktop/CRUD/env/lib/python3.6/site-packages/rest_framework/viewsets.py", line 114, in view
    return self.dispatch(request, *args, **kwargs)
  File "/home/rohit/Desktop/CRUD/env/lib/python3.6/site-packages/rest_framework/views.py", line 505, in dispatch
    response = self.handle_exception(exc)
  File "/home/rohit/Desktop/CRUD/env/lib/python3.6/site-packages/rest_framework/views.py", line 465, in handle_exception
    self.raise_uncaught_exception(exc)
  File "/home/rohit/Desktop/CRUD/env/lib/python3.6/site-packages/rest_framework/views.py", line 476, in raise_uncaught_exception
    raise exc
  File "/home/rohit/Desktop/CRUD/env/lib/python3.6/site-packages/rest_framework/views.py", line 502, in dispatch
    response = handler(request, *args, **kwargs)
  File "/home/rohit/Desktop/CRUD/POLITICS/district/decorator.py", line 36, in __call__
    return self.view_function(self, request, *args, **kwargs)
  File "/home/rohit/Desktop/CRUD/POLITICS/district/views.py", line 104, in list
    self.logger.error("Exception occured is = " + str(e))
AttributeError: 'DecorClass' object has no attribute 'logger'
2020-12-01 16:18:50,550 [ERROR] {/home/rohit/Desktop/CRUD/env/lib/python3.6/site-packages/django/utils/log.py:230} : Internal Server Error: /district/View_Set/TVS/
Traceback (most recent call last):
  File "/home/rohit/Desktop/CRUD/POLITICS/district/views.py", line 85, in list
    return Response(str(query_set1.query))
AttributeError: 'Language' object has no attribute 'query'

During handling of the above exception, another exception occurred:

Traceback (most recent call last):
  File "/home/rohit/Desktop/CRUD/env/lib/python3.6/site-packages/django/core/handlers/exception.py", line 47, in inner
    response = get_response(request)
  File "/home/rohit/Desktop/CRUD/env/lib/python3.6/site-packages/django/core/handlers/base.py", line 179, in _get_response
    response = wrapped_callback(request, *callback_args, **callback_kwargs)
  File "/home/rohit/Desktop/CRUD/env/lib/python3.6/site-packages/django/views/decorators/csrf.py", line 54, in wrapped_view
    return view_func(*args, **kwargs)
  File "/home/rohit/Desktop/CRUD/env/lib/python3.6/site-packages/rest_framework/viewsets.py", line 114, in view
    return self.dispatch(request, *args, **kwargs)
  File "/home/rohit/Desktop/CRUD/env/lib/python3.6/site-packages/rest_framework/views.py", line 505, in dispatch
    response = self.handle_exception(exc)
  File "/home/rohit/Desktop/CRUD/env/lib/python3.6/site-packages/rest_framework/views.py", line 465, in handle_exception
    self.raise_uncaught_exception(exc)
  File "/home/rohit/Desktop/CRUD/env/lib/python3.6/site-packages/rest_framework/views.py", line 476, in raise_uncaught_exception
    raise exc
  File "/home/rohit/Desktop/CRUD/env/lib/python3.6/site-packages/rest_framework/views.py", line 502, in dispatch
    response = handler(request, *args, **kwargs)
  File "/home/rohit/Desktop/CRUD/POLITICS/district/decorator.py", line 36, in __call__
    return self.view_function(self, request, *args, **kwargs)
  File "/home/rohit/Desktop/CRUD/POLITICS/district/views.py", line 104, in list
    self.logger.error("Exception occured is = " + str(e))
AttributeError: 'DecorClass' object has no attribute 'logger'
2020-12-01 21:32:59,686 [ERROR] {/home/rohit/Desktop/CRUD/env/lib/python3.6/site-packages/django/utils/log.py:230} : Internal Server Error: /district/View_Set/TVS/
Traceback (most recent call last):
  File "/home/rohit/Desktop/CRUD/env/lib/python3.6/site-packages/django/core/handlers/exception.py", line 47, in inner
    response = get_response(request)
  File "/home/rohit/Desktop/CRUD/env/lib/python3.6/site-packages/django/core/handlers/base.py", line 179, in _get_response
    response = wrapped_callback(request, *callback_args, **callback_kwargs)
  File "/home/rohit/Desktop/CRUD/env/lib/python3.6/site-packages/django/views/decorators/csrf.py", line 54, in wrapped_view
    return view_func(*args, **kwargs)
  File "/home/rohit/Desktop/CRUD/env/lib/python3.6/site-packages/rest_framework/viewsets.py", line 114, in view
    return self.dispatch(request, *args, **kwargs)
  File "/home/rohit/Desktop/CRUD/env/lib/python3.6/site-packages/rest_framework/views.py", line 505, in dispatch
    response = self.handle_exception(exc)
  File "/home/rohit/Desktop/CRUD/env/lib/python3.6/site-packages/rest_framework/views.py", line 465, in handle_exception
    self.raise_uncaught_exception(exc)
  File "/home/rohit/Desktop/CRUD/env/lib/python3.6/site-packages/rest_framework/views.py", line 476, in raise_uncaught_exception
    raise exc
  File "/home/rohit/Desktop/CRUD/env/lib/python3.6/site-packages/rest_framework/views.py", line 502, in dispatch
    response = handler(request, *args, **kwargs)
  File "/home/rohit/Desktop/CRUD/POLITICS/district/decorator.py", line 34, in __call__
    print("User Name is = "+str(request.user.name))
AttributeError: 'User' object has no attribute 'name'
2020-12-02 18:06:30,718 [ERROR] {/home/rohit/Desktop/CRUD/env/lib/python3.6/site-packages/django/core/handlers/exception.py:90} : Invalid HTTP_HOST header: '127.0.0.1:8000'. You may need to add '127.0.0.1' to ALLOWED_HOSTS.
2020-12-03 11:36:53,207 [ERROR] {/home/rohit/Desktop/CRUD/env/lib/python3.6/site-packages/django/utils/log.py:230} : Internal Server Error: /district/View_Set/TVS/
Traceback (most recent call last):
  File "/home/rohit/Desktop/CRUD/env/lib/python3.6/site-packages/django/core/handlers/exception.py", line 47, in inner
    response = get_response(request)
  File "/home/rohit/Desktop/CRUD/env/lib/python3.6/site-packages/django/core/handlers/base.py", line 179, in _get_response
    response = wrapped_callback(request, *callback_args, **callback_kwargs)
  File "/home/rohit/Desktop/CRUD/env/lib/python3.6/site-packages/django/views/decorators/csrf.py", line 54, in wrapped_view
    return view_func(*args, **kwargs)
  File "/home/rohit/Desktop/CRUD/env/lib/python3.6/site-packages/rest_framework/viewsets.py", line 114, in view
    return self.dispatch(request, *args, **kwargs)
  File "/home/rohit/Desktop/CRUD/env/lib/python3.6/site-packages/rest_framework/views.py", line 505, in dispatch
    response = self.handle_exception(exc)
  File "/home/rohit/Desktop/CRUD/env/lib/python3.6/site-packages/rest_framework/views.py", line 465, in handle_exception
    self.raise_uncaught_exception(exc)
  File "/home/rohit/Desktop/CRUD/env/lib/python3.6/site-packages/rest_framework/views.py", line 476, in raise_uncaught_exception
    raise exc
  File "/home/rohit/Desktop/CRUD/env/lib/python3.6/site-packages/rest_framework/views.py", line 502, in dispatch
    response = handler(request, *args, **kwargs)
  File "/home/rohit/Desktop/CRUD/POLITICS/district/decorator.py", line 36, in __call__
    print("User Name is = "+str(request.user.name))
AttributeError: 'User' object has no attribute 'name'
2020-12-03 13:12:12,275 [ERROR] {/home/rohit/Desktop/CRUD/env/lib/python3.6/site-packages/django/utils/log.py:230} : Internal Server Error: /district/View_Set/TVS/
Traceback (most recent call last):
  File "/home/rohit/Desktop/CRUD/env/lib/python3.6/site-packages/django/core/handlers/exception.py", line 47, in inner
    response = get_response(request)
  File "/home/rohit/Desktop/CRUD/env/lib/python3.6/site-packages/django/core/handlers/base.py", line 179, in _get_response
    response = wrapped_callback(request, *callback_args, **callback_kwargs)
  File "/home/rohit/Desktop/CRUD/env/lib/python3.6/site-packages/django/views/decorators/csrf.py", line 54, in wrapped_view
    return view_func(*args, **kwargs)
  File "/home/rohit/Desktop/CRUD/env/lib/python3.6/site-packages/rest_framework/viewsets.py", line 114, in view
    return self.dispatch(request, *args, **kwargs)
  File "/home/rohit/Desktop/CRUD/env/lib/python3.6/site-packages/rest_framework/views.py", line 505, in dispatch
    response = self.handle_exception(exc)
  File "/home/rohit/Desktop/CRUD/env/lib/python3.6/site-packages/rest_framework/views.py", line 465, in handle_exception
    self.raise_uncaught_exception(exc)
  File "/home/rohit/Desktop/CRUD/env/lib/python3.6/site-packages/rest_framework/views.py", line 476, in raise_uncaught_exception
    raise exc
  File "/home/rohit/Desktop/CRUD/env/lib/python3.6/site-packages/rest_framework/views.py", line 502, in dispatch
    response = handler(request, *args, **kwargs)
  File "/home/rohit/Desktop/CRUD/POLITICS/district/decorator.py", line 36, in __call__
    print("User Name is = "+str(request.user.name))
AttributeError: 'User' object has no attribute 'name'
2020-12-03 16:30:06,949 [ERROR] {/home/rohit/Desktop/CRUD/env/lib/python3.6/site-packages/django/utils/log.py:230} : Internal Server Error: /district/View_Set/TVS/
Traceback (most recent call last):
  File "/home/rohit/Desktop/CRUD/env/lib/python3.6/site-packages/django/core/handlers/exception.py", line 47, in inner
    response = get_response(request)
  File "/home/rohit/Desktop/CRUD/env/lib/python3.6/site-packages/django/core/handlers/base.py", line 179, in _get_response
    response = wrapped_callback(request, *callback_args, **callback_kwargs)
  File "/home/rohit/Desktop/CRUD/env/lib/python3.6/site-packages/django/views/decorators/csrf.py", line 54, in wrapped_view
    return view_func(*args, **kwargs)
  File "/home/rohit/Desktop/CRUD/env/lib/python3.6/site-packages/rest_framework/viewsets.py", line 114, in view
    return self.dispatch(request, *args, **kwargs)
  File "/home/rohit/Desktop/CRUD/env/lib/python3.6/site-packages/rest_framework/views.py", line 505, in dispatch
    response = self.handle_exception(exc)
  File "/home/rohit/Desktop/CRUD/env/lib/python3.6/site-packages/rest_framework/views.py", line 465, in handle_exception
    self.raise_uncaught_exception(exc)
  File "/home/rohit/Desktop/CRUD/env/lib/python3.6/site-packages/rest_framework/views.py", line 476, in raise_uncaught_exception
    raise exc
  File "/home/rohit/Desktop/CRUD/env/lib/python3.6/site-packages/rest_framework/views.py", line 502, in dispatch
    response = handler(request, *args, **kwargs)
  File "/home/rohit/Desktop/CRUD/POLITICS/district/decorator.py", line 37, in __call__
    if a == 101:
NameError: name 'a' is not defined
2020-12-15 16:05:38,317 [ERROR] {/home/rohit/Desktop/CRUD/env/lib/python3.6/site-packages/django/utils/log.py:230} : Internal Server Error: /district/View_Set/TVS/
2020-12-21 13:54:47,582 [ERROR] {/home/rohit/Desktop/CRUD/env/lib/python3.6/site-packages/django/utils/log.py:230} : Internal Server Error: /district/View_Set/TVS/
2020-12-31 20:53:38,885 [ERROR] {/home/rohit/Desktop/CRUD/env/lib/python3.6/site-packages/django/utils/log.py:230} : Internal Server Error: /district/oneToMany
Traceback (most recent call last):
  File "/home/rohit/Desktop/CRUD/env/lib/python3.6/site-packages/django/core/handlers/exception.py", line 47, in inner
    response = get_response(request)
  File "/home/rohit/Desktop/CRUD/env/lib/python3.6/site-packages/django/core/handlers/base.py", line 179, in _get_response
    response = wrapped_callback(request, *callback_args, **callback_kwargs)
  File "/home/rohit/Desktop/CRUD/env/lib/python3.6/site-packages/django/views/decorators/csrf.py", line 54, in wrapped_view
    return view_func(*args, **kwargs)
  File "/home/rohit/Desktop/CRUD/env/lib/python3.6/site-packages/django/views/generic/base.py", line 70, in view
    return self.dispatch(request, *args, **kwargs)
  File "/home/rohit/Desktop/CRUD/env/lib/python3.6/site-packages/rest_framework/views.py", line 505, in dispatch
    response = self.handle_exception(exc)
  File "/home/rohit/Desktop/CRUD/env/lib/python3.6/site-packages/rest_framework/views.py", line 465, in handle_exception
    self.raise_uncaught_exception(exc)
  File "/home/rohit/Desktop/CRUD/env/lib/python3.6/site-packages/rest_framework/views.py", line 476, in raise_uncaught_exception
    raise exc
  File "/home/rohit/Desktop/CRUD/env/lib/python3.6/site-packages/rest_framework/views.py", line 502, in dispatch
    response = handler(request, *args, **kwargs)
  File "/home/rohit/Desktop/CRUD/env/lib/python3.6/site-packages/rest_framework/decorators.py", line 50, in handler
    return func(*args, **kwargs)
  File "/home/rohit/Desktop/CRUD/POLITICS/district/views.py", line 429, in one_to_many
    print(annotate_query_set[0].sum)
AttributeError: 'dict' object has no attribute 'sum'
2021-01-10 21:44:13,144 [ERROR] {/home/rohit/Desktop/CRUD/env/lib/python3.6/site-packages/django/utils/log.py:230} : Internal Server Error: /district/View_Set/VSS
Traceback (most recent call last):
  File "/home/rohit/Desktop/CRUD/env/lib/python3.6/site-packages/django/core/handlers/exception.py", line 47, in inner
    response = get_response(request)
  File "/home/rohit/Desktop/CRUD/env/lib/python3.6/site-packages/django/utils/deprecation.py", line 113, in __call__
    response = self.process_request(request)
  File "/home/rohit/Desktop/CRUD/env/lib/python3.6/site-packages/django/middleware/common.py", line 54, in process_request
    path = self.get_full_path_with_slash(request)
  File "/home/rohit/Desktop/CRUD/env/lib/python3.6/site-packages/django/middleware/common.py", line 94, in get_full_path_with_slash
    'url': request.get_host() + new_path,
RuntimeError: You called this URL via POST, but the URL doesn't end in a slash and you have APPEND_SLASH set. Django can't redirect to the slash URL while maintaining POST data. Change your form to point to 127.0.0.1:8000/district/View_Set/VSS/ (note the trailing slash), or set APPEND_SLASH=False in your Django settings.
2021-01-13 22:22:49,316 [ERROR] {/home/rohit/Desktop/CRUD/env/lib/python3.6/site-packages/django/utils/log.py:230} : Internal Server Error: /district/View_Set/VSS/
Traceback (most recent call last):
  File "/home/rohit/Desktop/CRUD/env/lib/python3.6/site-packages/django/core/handlers/exception.py", line 47, in inner
    response = get_response(request)
  File "/home/rohit/Desktop/CRUD/env/lib/python3.6/site-packages/django/core/handlers/base.py", line 179, in _get_response
    response = wrapped_callback(request, *callback_args, **callback_kwargs)
  File "/home/rohit/Desktop/CRUD/env/lib/python3.6/site-packages/django/views/decorators/csrf.py", line 54, in wrapped_view
    return view_func(*args, **kwargs)
  File "/home/rohit/Desktop/CRUD/env/lib/python3.6/site-packages/rest_framework/viewsets.py", line 114, in view
    return self.dispatch(request, *args, **kwargs)
  File "/home/rohit/Desktop/CRUD/env/lib/python3.6/site-packages/rest_framework/views.py", line 505, in dispatch
    response = self.handle_exception(exc)
  File "/home/rohit/Desktop/CRUD/env/lib/python3.6/site-packages/rest_framework/views.py", line 465, in handle_exception
    self.raise_uncaught_exception(exc)
  File "/home/rohit/Desktop/CRUD/env/lib/python3.6/site-packages/rest_framework/views.py", line 476, in raise_uncaught_exception
    raise exc
  File "/home/rohit/Desktop/CRUD/env/lib/python3.6/site-packages/rest_framework/views.py", line 493, in dispatch
    self.initial(request, *args, **kwargs)
  File "/home/rohit/Desktop/CRUD/env/lib/python3.6/site-packages/rest_framework/views.py", line 411, in initial
    self.check_permissions(request)
  File "/home/rohit/Desktop/CRUD/env/lib/python3.6/site-packages/rest_framework/views.py", line 332, in check_permissions
    if not permission.has_permission(request, self):
  File "/home/rohit/Desktop/CRUD/POLITICS/district/permmissions.py", line 11, in has_permission
    name = request.data.query_params("name")
AttributeError: 'dict' object has no attribute 'query_params'
2021-01-13 22:23:07,417 [ERROR] {/home/rohit/Desktop/CRUD/env/lib/python3.6/site-packages/django/utils/log.py:230} : Internal Server Error: /district/View_Set/VSS/
Traceback (most recent call last):
  File "/home/rohit/Desktop/CRUD/env/lib/python3.6/site-packages/django/core/handlers/exception.py", line 47, in inner
    response = get_response(request)
  File "/home/rohit/Desktop/CRUD/env/lib/python3.6/site-packages/django/core/handlers/base.py", line 179, in _get_response
    response = wrapped_callback(request, *callback_args, **callback_kwargs)
  File "/home/rohit/Desktop/CRUD/env/lib/python3.6/site-packages/django/views/decorators/csrf.py", line 54, in wrapped_view
    return view_func(*args, **kwargs)
  File "/home/rohit/Desktop/CRUD/env/lib/python3.6/site-packages/rest_framework/viewsets.py", line 114, in view
    return self.dispatch(request, *args, **kwargs)
  File "/home/rohit/Desktop/CRUD/env/lib/python3.6/site-packages/rest_framework/views.py", line 505, in dispatch
    response = self.handle_exception(exc)
  File "/home/rohit/Desktop/CRUD/env/lib/python3.6/site-packages/rest_framework/views.py", line 465, in handle_exception
    self.raise_uncaught_exception(exc)
  File "/home/rohit/Desktop/CRUD/env/lib/python3.6/site-packages/rest_framework/views.py", line 476, in raise_uncaught_exception
    raise exc
  File "/home/rohit/Desktop/CRUD/env/lib/python3.6/site-packages/rest_framework/views.py", line 493, in dispatch
    self.initial(request, *args, **kwargs)
  File "/home/rohit/Desktop/CRUD/env/lib/python3.6/site-packages/rest_framework/views.py", line 411, in initial
    self.check_permissions(request)
  File "/home/rohit/Desktop/CRUD/env/lib/python3.6/site-packages/rest_framework/views.py", line 332, in check_permissions
    if not permission.has_permission(request, self):
  File "/home/rohit/Desktop/CRUD/POLITICS/district/permmissions.py", line 11, in has_permission
    name = request.query_params("name")
TypeError: 'QueryDict' object is not callable
2021-01-17 21:23:30,947 [ERROR] {/home/rohit/Desktop/CRUD/env/lib/python3.6/site-packages/django/utils/log.py:230} : Internal Server Error: /district/DCBV/
Traceback (most recent call last):
  File "/home/rohit/Desktop/CRUD/env/lib/python3.6/site-packages/django/core/handlers/exception.py", line 47, in inner
    response = get_response(request)
  File "/home/rohit/Desktop/CRUD/env/lib/python3.6/site-packages/django/core/handlers/base.py", line 202, in _get_response
    response = response.render()
  File "/home/rohit/Desktop/CRUD/env/lib/python3.6/site-packages/django/template/response.py", line 105, in render
    self.content = self.rendered_content
  File "/home/rohit/Desktop/CRUD/env/lib/python3.6/site-packages/rest_framework/response.py", line 55, in rendered_content
    assert renderer, ".accepted_renderer not set on Response"
AssertionError: .accepted_renderer not set on Response
2021-01-17 21:23:41,624 [ERROR] {/home/rohit/Desktop/CRUD/env/lib/python3.6/site-packages/django/utils/log.py:230} : Internal Server Error: /district/DCBV/
Traceback (most recent call last):
  File "/home/rohit/Desktop/CRUD/env/lib/python3.6/site-packages/django/core/handlers/exception.py", line 47, in inner
    response = get_response(request)
  File "/home/rohit/Desktop/CRUD/env/lib/python3.6/site-packages/django/core/handlers/base.py", line 202, in _get_response
    response = response.render()
  File "/home/rohit/Desktop/CRUD/env/lib/python3.6/site-packages/django/template/response.py", line 105, in render
    self.content = self.rendered_content
  File "/home/rohit/Desktop/CRUD/env/lib/python3.6/site-packages/rest_framework/response.py", line 55, in rendered_content
    assert renderer, ".accepted_renderer not set on Response"
AssertionError: .accepted_renderer not set on Response
2021-01-17 21:26:05,536 [ERROR] {/home/rohit/Desktop/CRUD/env/lib/python3.6/site-packages/django/utils/log.py:230} : Internal Server Error: /district/DCBV/
Traceback (most recent call last):
  File "/home/rohit/Desktop/CRUD/env/lib/python3.6/site-packages/django/core/handlers/exception.py", line 47, in inner
    response = get_response(request)
  File "/home/rohit/Desktop/CRUD/env/lib/python3.6/site-packages/django/core/handlers/base.py", line 202, in _get_response
    response = response.render()
  File "/home/rohit/Desktop/CRUD/env/lib/python3.6/site-packages/django/template/response.py", line 105, in render
    self.content = self.rendered_content
  File "/home/rohit/Desktop/CRUD/env/lib/python3.6/site-packages/rest_framework/response.py", line 55, in rendered_content
    assert renderer, ".accepted_renderer not set on Response"
AssertionError: .accepted_renderer not set on Response
2021-01-19 11:42:12,597 [ERROR] {/home/rohit/Desktop/CRUD/env/lib/python3.6/site-packages/django/utils/log.py:228} : Internal Server Error: /district/DCBV/
Traceback (most recent call last):
  File "/home/rohit/Desktop/CRUD/env/lib/python3.6/site-packages/django/core/handlers/exception.py", line 34, in inner
    response = get_response(request)
  File "/home/rohit/Desktop/CRUD/env/lib/python3.6/site-packages/django/core/handlers/base.py", line 145, in _get_response
    response = self.process_exception_by_middleware(e, request)
  File "/home/rohit/Desktop/CRUD/env/lib/python3.6/site-packages/django/core/handlers/base.py", line 143, in _get_response
    response = response.render()
  File "/home/rohit/Desktop/CRUD/env/lib/python3.6/site-packages/django/template/response.py", line 105, in render
    self.content = self.rendered_content
  File "/home/rohit/Desktop/CRUD/env/lib/python3.6/site-packages/rest_framework/response.py", line 55, in rendered_content
    assert renderer, ".accepted_renderer not set on Response"
AssertionError: .accepted_renderer not set on Response
2021-01-19 11:50:11,342 [ERROR] {/home/rohit/Desktop/CRUD/env/lib/python3.6/site-packages/django/utils/log.py:228} : Internal Server Error: /district/DCBV/
Traceback (most recent call last):
  File "/home/rohit/Desktop/CRUD/env/lib/python3.6/site-packages/django/core/handlers/exception.py", line 34, in inner
    response = get_response(request)
  File "/home/rohit/Desktop/CRUD/env/lib/python3.6/site-packages/django/core/handlers/base.py", line 115, in _get_response
    response = self.process_exception_by_middleware(e, request)
  File "/home/rohit/Desktop/CRUD/env/lib/python3.6/site-packages/django/core/handlers/base.py", line 113, in _get_response
    response = wrapped_callback(request, *callback_args, **callback_kwargs)
  File "/home/rohit/Desktop/CRUD/env/lib/python3.6/site-packages/django/views/generic/base.py", line 71, in view
    return self.dispatch(request, *args, **kwargs)
  File "/home/rohit/Desktop/CRUD/env/lib/python3.6/site-packages/django/views/generic/base.py", line 97, in dispatch
    return handler(request, *args, **kwargs)
  File "/home/rohit/Desktop/CRUD/POLITICS/district/views.py", line 43, in get
    return render(request, 'allCountry.html', )
  File "/home/rohit/Desktop/CRUD/env/lib/python3.6/site-packages/django/shortcuts.py", line 19, in render
    content = loader.render_to_string(template_name, context, request, using=using)
  File "/home/rohit/Desktop/CRUD/env/lib/python3.6/site-packages/django/template/loader.py", line 61, in render_to_string
    template = get_template(template_name, using=using)
  File "/home/rohit/Desktop/CRUD/env/lib/python3.6/site-packages/django/template/loader.py", line 19, in get_template
    raise TemplateDoesNotExist(template_name, chain=chain)
django.template.exceptions.TemplateDoesNotExist: allCountry.html
2021-01-22 17:08:18,541 [ERROR] {/home/rohit/Desktop/CRUD/env/lib/python3.6/site-packages/django/utils/log.py:228} : Internal Server Error: /district/DLV
Traceback (most recent call last):
  File "/home/rohit/Desktop/CRUD/env/lib/python3.6/site-packages/django/core/handlers/exception.py", line 34, in inner
    response = get_response(request)
  File "/home/rohit/Desktop/CRUD/env/lib/python3.6/site-packages/django/core/handlers/base.py", line 145, in _get_response
    response = self.process_exception_by_middleware(e, request)
  File "/home/rohit/Desktop/CRUD/env/lib/python3.6/site-packages/django/core/handlers/base.py", line 143, in _get_response
    response = response.render()
  File "/home/rohit/Desktop/CRUD/env/lib/python3.6/site-packages/django/template/response.py", line 105, in render
    self.content = self.rendered_content
  File "/home/rohit/Desktop/CRUD/env/lib/python3.6/site-packages/django/template/response.py", line 81, in rendered_content
    template = self.resolve_template(self.template_name)
  File "/home/rohit/Desktop/CRUD/env/lib/python3.6/site-packages/django/template/response.py", line 63, in resolve_template
    return select_template(template, using=self.using)
  File "/home/rohit/Desktop/CRUD/env/lib/python3.6/site-packages/django/template/loader.py", line 47, in select_template
    raise TemplateDoesNotExist(', '.join(template_name_list), chain=chain)
django.template.exceptions.TemplateDoesNotExist: district/language_list.html
2021-01-22 21:35:23,914 [ERROR] {/home/rohit/Desktop/CRUD/env/lib/python3.6/site-packages/django/utils/log.py:228} : Internal Server Error: /district/DLV
Traceback (most recent call last):
  File "/home/rohit/Desktop/CRUD/env/lib/python3.6/site-packages/django/core/handlers/exception.py", line 34, in inner
    response = get_response(request)
  File "/home/rohit/Desktop/CRUD/env/lib/python3.6/site-packages/django/core/handlers/base.py", line 115, in _get_response
    response = self.process_exception_by_middleware(e, request)
  File "/home/rohit/Desktop/CRUD/env/lib/python3.6/site-packages/django/core/handlers/base.py", line 113, in _get_response
    response = wrapped_callback(request, *callback_args, **callback_kwargs)
  File "/home/rohit/Desktop/CRUD/env/lib/python3.6/site-packages/django/views/generic/base.py", line 71, in view
    return self.dispatch(request, *args, **kwargs)
  File "/home/rohit/Desktop/CRUD/env/lib/python3.6/site-packages/django/views/generic/base.py", line 97, in dispatch
    return handler(request, *args, **kwargs)
  File "/home/rohit/Desktop/CRUD/env/lib/python3.6/site-packages/django/views/generic/list.py", line 142, in get
    self.object_list = self.get_queryset()
  File "/home/rohit/Desktop/CRUD/POLITICS/district/views.py", line 71, in get_queryset
    query_set = Language.object.filter(name='PHP')
AttributeError: type object 'Language' has no attribute 'object'
2021-01-25 12:58:22,952 [ERROR] {/home/rohit/Desktop/CRUD/env/lib/python3.6/site-packages/django/utils/log.py:228} : Internal Server Error: /district/oneToMany
Traceback (most recent call last):
  File "/home/rohit/Desktop/CRUD/env/lib/python3.6/site-packages/django/core/handlers/exception.py", line 34, in inner
    response = get_response(request)
  File "/home/rohit/Desktop/CRUD/env/lib/python3.6/site-packages/django/core/handlers/base.py", line 115, in _get_response
    response = self.process_exception_by_middleware(e, request)
  File "/home/rohit/Desktop/CRUD/env/lib/python3.6/site-packages/django/core/handlers/base.py", line 113, in _get_response
    response = wrapped_callback(request, *callback_args, **callback_kwargs)
  File "/home/rohit/Desktop/CRUD/env/lib/python3.6/site-packages/django/views/decorators/csrf.py", line 54, in wrapped_view
    return view_func(*args, **kwargs)
  File "/home/rohit/Desktop/CRUD/env/lib/python3.6/site-packages/django/views/generic/base.py", line 71, in view
    return self.dispatch(request, *args, **kwargs)
  File "/home/rohit/Desktop/CRUD/env/lib/python3.6/site-packages/rest_framework/views.py", line 505, in dispatch
    response = self.handle_exception(exc)
  File "/home/rohit/Desktop/CRUD/env/lib/python3.6/site-packages/rest_framework/views.py", line 465, in handle_exception
    self.raise_uncaught_exception(exc)
  File "/home/rohit/Desktop/CRUD/env/lib/python3.6/site-packages/rest_framework/views.py", line 476, in raise_uncaught_exception
    raise exc
  File "/home/rohit/Desktop/CRUD/env/lib/python3.6/site-packages/rest_framework/views.py", line 502, in dispatch
    response = handler(request, *args, **kwargs)
  File "/home/rohit/Desktop/CRUD/env/lib/python3.6/site-packages/rest_framework/decorators.py", line 50, in handler
    return func(*args, **kwargs)
  File "/home/rohit/Desktop/CRUD/POLITICS/district/views.py", line 480, in one_to_many
    q1 = Language.get_all_language()
TypeError: get_all_language() missing 1 required positional argument: 'self'
2021-01-27 15:16:11,836 [ERROR] {/home/rohit/Desktop/CRUD/env/lib/python3.6/site-packages/django/utils/log.py:228} : Internal Server Error: /district/oneToMany
2021-01-27 15:16:23,825 [ERROR] {/home/rohit/Desktop/CRUD/env/lib/python3.6/site-packages/django/utils/log.py:228} : Internal Server Error: /district/oneToMany
2021-01-27 15:16:32,534 [ERROR] {/home/rohit/Desktop/CRUD/env/lib/python3.6/site-packages/django/utils/log.py:228} : Internal Server Error: /district/oneToMany
2021-01-29 10:45:59,117 [ERROR] {/home/rohit/Desktop/CRUD/env/lib/python3.6/site-packages/django/utils/log.py:228} : Internal Server Error: /district/oneToMany
2021-01-29 19:25:05,119 [ERROR] {/home/rohit/Desktop/CRUD/env/lib/python3.6/site-packages/django/utils/log.py:228} : Internal Server Error: /district/oneToMany
Traceback (most recent call last):
  File "/home/rohit/Desktop/CRUD/env/lib/python3.6/site-packages/django/core/handlers/exception.py", line 34, in inner
    response = get_response(request)
  File "/home/rohit/Desktop/CRUD/env/lib/python3.6/site-packages/django/core/handlers/base.py", line 115, in _get_response
    response = self.process_exception_by_middleware(e, request)
  File "/home/rohit/Desktop/CRUD/env/lib/python3.6/site-packages/django/core/handlers/base.py", line 113, in _get_response
    response = wrapped_callback(request, *callback_args, **callback_kwargs)
  File "/home/rohit/Desktop/CRUD/env/lib/python3.6/site-packages/django/views/decorators/csrf.py", line 54, in wrapped_view
    return view_func(*args, **kwargs)
  File "/home/rohit/Desktop/CRUD/env/lib/python3.6/site-packages/django/views/generic/base.py", line 71, in view
    return self.dispatch(request, *args, **kwargs)
  File "/home/rohit/Desktop/CRUD/env/lib/python3.6/site-packages/rest_framework/views.py", line 505, in dispatch
    response = self.handle_exception(exc)
  File "/home/rohit/Desktop/CRUD/env/lib/python3.6/site-packages/rest_framework/views.py", line 465, in handle_exception
    self.raise_uncaught_exception(exc)
  File "/home/rohit/Desktop/CRUD/env/lib/python3.6/site-packages/rest_framework/views.py", line 476, in raise_uncaught_exception
    raise exc
  File "/home/rohit/Desktop/CRUD/env/lib/python3.6/site-packages/rest_framework/views.py", line 502, in dispatch
    response = handler(request, *args, **kwargs)
  File "/home/rohit/Desktop/CRUD/env/lib/python3.6/site-packages/rest_framework/decorators.py", line 50, in handler
    return func(*args, **kwargs)
  File "/home/rohit/Desktop/CRUD/POLITICS/district/views.py", line 477, in one_to_many
    q2 = Language.objects.order_by('-id')[:-1]
  File "/home/rohit/Desktop/CRUD/env/lib/python3.6/site-packages/django/db/models/query.py", line 293, in __getitem__
    "Negative indexing is not supported."
AssertionError: Negative indexing is not supported.
2021-01-29 19:28:02,148 [ERROR] {/home/rohit/Desktop/CRUD/env/lib/python3.6/site-packages/django/utils/log.py:228} : Internal Server Error: /district/oneToMany
Traceback (most recent call last):
  File "/home/rohit/Desktop/CRUD/env/lib/python3.6/site-packages/django/core/handlers/exception.py", line 34, in inner
    response = get_response(request)
  File "/home/rohit/Desktop/CRUD/env/lib/python3.6/site-packages/django/core/handlers/base.py", line 115, in _get_response
    response = self.process_exception_by_middleware(e, request)
  File "/home/rohit/Desktop/CRUD/env/lib/python3.6/site-packages/django/core/handlers/base.py", line 113, in _get_response
    response = wrapped_callback(request, *callback_args, **callback_kwargs)
  File "/home/rohit/Desktop/CRUD/env/lib/python3.6/site-packages/django/views/decorators/csrf.py", line 54, in wrapped_view
    return view_func(*args, **kwargs)
  File "/home/rohit/Desktop/CRUD/env/lib/python3.6/site-packages/django/views/generic/base.py", line 71, in view
    return self.dispatch(request, *args, **kwargs)
  File "/home/rohit/Desktop/CRUD/env/lib/python3.6/site-packages/rest_framework/views.py", line 505, in dispatch
    response = self.handle_exception(exc)
  File "/home/rohit/Desktop/CRUD/env/lib/python3.6/site-packages/rest_framework/views.py", line 465, in handle_exception
    self.raise_uncaught_exception(exc)
  File "/home/rohit/Desktop/CRUD/env/lib/python3.6/site-packages/rest_framework/views.py", line 476, in raise_uncaught_exception
    raise exc
  File "/home/rohit/Desktop/CRUD/env/lib/python3.6/site-packages/rest_framework/views.py", line 502, in dispatch
    response = handler(request, *args, **kwargs)
  File "/home/rohit/Desktop/CRUD/env/lib/python3.6/site-packages/rest_framework/decorators.py", line 50, in handler
    return func(*args, **kwargs)
  File "/home/rohit/Desktop/CRUD/POLITICS/district/views.py", line 478, in one_to_many
    return Response(str(q2.query))
  File "/home/rohit/Desktop/CRUD/env/lib/python3.6/site-packages/django/db/models/sql/query.py", line 264, in __str__
    sql, params = self.sql_with_params()
  File "/home/rohit/Desktop/CRUD/env/lib/python3.6/site-packages/django/db/models/sql/query.py", line 272, in sql_with_params
    return self.get_compiler(DEFAULT_DB_ALIAS).as_sql()
  File "/home/rohit/Desktop/CRUD/env/lib/python3.6/site-packages/django/db/models/sql/compiler.py", line 506, in as_sql
    where, w_params = self.compile(self.where) if self.where is not None else ("", [])
  File "/home/rohit/Desktop/CRUD/env/lib/python3.6/site-packages/django/db/models/sql/compiler.py", line 423, in compile
    sql, params = node.as_sql(self, self.connection)
  File "/home/rohit/Desktop/CRUD/env/lib/python3.6/site-packages/django/db/models/sql/where.py", line 99, in as_sql
    raise EmptyResultSet
django.core.exceptions.EmptyResultSet
2021-01-29 19:28:39,013 [ERROR] {/home/rohit/Desktop/CRUD/env/lib/python3.6/site-packages/django/utils/log.py:228} : Internal Server Error: /district/oneToMany
Traceback (most recent call last):
  File "/home/rohit/Desktop/CRUD/env/lib/python3.6/site-packages/django/core/handlers/exception.py", line 34, in inner
    response = get_response(request)
  File "/home/rohit/Desktop/CRUD/env/lib/python3.6/site-packages/django/core/handlers/base.py", line 115, in _get_response
    response = self.process_exception_by_middleware(e, request)
  File "/home/rohit/Desktop/CRUD/env/lib/python3.6/site-packages/django/core/handlers/base.py", line 113, in _get_response
    response = wrapped_callback(request, *callback_args, **callback_kwargs)
  File "/home/rohit/Desktop/CRUD/env/lib/python3.6/site-packages/django/views/decorators/csrf.py", line 54, in wrapped_view
    return view_func(*args, **kwargs)
  File "/home/rohit/Desktop/CRUD/env/lib/python3.6/site-packages/django/views/generic/base.py", line 71, in view
    return self.dispatch(request, *args, **kwargs)
  File "/home/rohit/Desktop/CRUD/env/lib/python3.6/site-packages/rest_framework/views.py", line 505, in dispatch
    response = self.handle_exception(exc)
  File "/home/rohit/Desktop/CRUD/env/lib/python3.6/site-packages/rest_framework/views.py", line 465, in handle_exception
    self.raise_uncaught_exception(exc)
  File "/home/rohit/Desktop/CRUD/env/lib/python3.6/site-packages/rest_framework/views.py", line 476, in raise_uncaught_exception
    raise exc
  File "/home/rohit/Desktop/CRUD/env/lib/python3.6/site-packages/rest_framework/views.py", line 502, in dispatch
    response = handler(request, *args, **kwargs)
  File "/home/rohit/Desktop/CRUD/env/lib/python3.6/site-packages/rest_framework/decorators.py", line 50, in handler
    return func(*args, **kwargs)
  File "/home/rohit/Desktop/CRUD/POLITICS/district/views.py", line 478, in one_to_many
    return Response(str(q2.query))
  File "/home/rohit/Desktop/CRUD/env/lib/python3.6/site-packages/django/db/models/sql/query.py", line 264, in __str__
    sql, params = self.sql_with_params()
  File "/home/rohit/Desktop/CRUD/env/lib/python3.6/site-packages/django/db/models/sql/query.py", line 272, in sql_with_params
    return self.get_compiler(DEFAULT_DB_ALIAS).as_sql()
  File "/home/rohit/Desktop/CRUD/env/lib/python3.6/site-packages/django/db/models/sql/compiler.py", line 506, in as_sql
    where, w_params = self.compile(self.where) if self.where is not None else ("", [])
  File "/home/rohit/Desktop/CRUD/env/lib/python3.6/site-packages/django/db/models/sql/compiler.py", line 423, in compile
    sql, params = node.as_sql(self, self.connection)
  File "/home/rohit/Desktop/CRUD/env/lib/python3.6/site-packages/django/db/models/sql/where.py", line 99, in as_sql
    raise EmptyResultSet
django.core.exceptions.EmptyResultSet
2021-01-29 19:30:24,369 [ERROR] {/home/rohit/Desktop/CRUD/env/lib/python3.6/site-packages/django/utils/log.py:228} : Internal Server Error: /district/oneToMany
Traceback (most recent call last):
  File "/home/rohit/Desktop/CRUD/env/lib/python3.6/site-packages/django/core/handlers/exception.py", line 34, in inner
    response = get_response(request)
  File "/home/rohit/Desktop/CRUD/env/lib/python3.6/site-packages/django/core/handlers/base.py", line 115, in _get_response
    response = self.process_exception_by_middleware(e, request)
  File "/home/rohit/Desktop/CRUD/env/lib/python3.6/site-packages/django/core/handlers/base.py", line 113, in _get_response
    response = wrapped_callback(request, *callback_args, **callback_kwargs)
  File "/home/rohit/Desktop/CRUD/env/lib/python3.6/site-packages/django/views/decorators/csrf.py", line 54, in wrapped_view
    return view_func(*args, **kwargs)
  File "/home/rohit/Desktop/CRUD/env/lib/python3.6/site-packages/django/views/generic/base.py", line 71, in view
    return self.dispatch(request, *args, **kwargs)
  File "/home/rohit/Desktop/CRUD/env/lib/python3.6/site-packages/rest_framework/views.py", line 505, in dispatch
    response = self.handle_exception(exc)
  File "/home/rohit/Desktop/CRUD/env/lib/python3.6/site-packages/rest_framework/views.py", line 465, in handle_exception
    self.raise_uncaught_exception(exc)
  File "/home/rohit/Desktop/CRUD/env/lib/python3.6/site-packages/rest_framework/views.py", line 476, in raise_uncaught_exception
    raise exc
  File "/home/rohit/Desktop/CRUD/env/lib/python3.6/site-packages/rest_framework/views.py", line 502, in dispatch
    response = handler(request, *args, **kwargs)
  File "/home/rohit/Desktop/CRUD/env/lib/python3.6/site-packages/rest_framework/decorators.py", line 50, in handler
    return func(*args, **kwargs)
  File "/home/rohit/Desktop/CRUD/POLITICS/district/views.py", line 478, in one_to_many
    return Response(str(q2.query))
AttributeError: 'Language' object has no attribute 'query'
2021-01-29 19:32:43,434 [ERROR] {/home/rohit/Desktop/CRUD/env/lib/python3.6/site-packages/django/utils/log.py:228} : Internal Server Error: /district/oneToMany
Traceback (most recent call last):
  File "/home/rohit/Desktop/CRUD/env/lib/python3.6/site-packages/django/core/handlers/exception.py", line 34, in inner
    response = get_response(request)
  File "/home/rohit/Desktop/CRUD/env/lib/python3.6/site-packages/django/core/handlers/base.py", line 115, in _get_response
    response = self.process_exception_by_middleware(e, request)
  File "/home/rohit/Desktop/CRUD/env/lib/python3.6/site-packages/django/core/handlers/base.py", line 113, in _get_response
    response = wrapped_callback(request, *callback_args, **callback_kwargs)
  File "/home/rohit/Desktop/CRUD/env/lib/python3.6/site-packages/django/views/decorators/csrf.py", line 54, in wrapped_view
    return view_func(*args, **kwargs)
  File "/home/rohit/Desktop/CRUD/env/lib/python3.6/site-packages/django/views/generic/base.py", line 71, in view
    return self.dispatch(request, *args, **kwargs)
  File "/home/rohit/Desktop/CRUD/env/lib/python3.6/site-packages/rest_framework/views.py", line 505, in dispatch
    response = self.handle_exception(exc)
  File "/home/rohit/Desktop/CRUD/env/lib/python3.6/site-packages/rest_framework/views.py", line 465, in handle_exception
    self.raise_uncaught_exception(exc)
  File "/home/rohit/Desktop/CRUD/env/lib/python3.6/site-packages/rest_framework/views.py", line 476, in raise_uncaught_exception
    raise exc
  File "/home/rohit/Desktop/CRUD/env/lib/python3.6/site-packages/rest_framework/views.py", line 502, in dispatch
    response = handler(request, *args, **kwargs)
  File "/home/rohit/Desktop/CRUD/env/lib/python3.6/site-packages/rest_framework/decorators.py", line 50, in handler
    return func(*args, **kwargs)
  File "/home/rohit/Desktop/CRUD/POLITICS/district/views.py", line 478, in one_to_many
    return Response(str(q2.query))
AttributeError: 'int' object has no attribute 'query'
2021-01-29 19:34:09,603 [ERROR] {/home/rohit/Desktop/CRUD/env/lib/python3.6/site-packages/django/utils/log.py:228} : Internal Server Error: /district/oneToMany
Traceback (most recent call last):
  File "/home/rohit/Desktop/CRUD/env/lib/python3.6/site-packages/django/core/handlers/exception.py", line 34, in inner
    response = get_response(request)
  File "/home/rohit/Desktop/CRUD/env/lib/python3.6/site-packages/django/core/handlers/base.py", line 115, in _get_response
    response = self.process_exception_by_middleware(e, request)
  File "/home/rohit/Desktop/CRUD/env/lib/python3.6/site-packages/django/core/handlers/base.py", line 113, in _get_response
    response = wrapped_callback(request, *callback_args, **callback_kwargs)
  File "/home/rohit/Desktop/CRUD/env/lib/python3.6/site-packages/django/views/decorators/csrf.py", line 54, in wrapped_view
    return view_func(*args, **kwargs)
  File "/home/rohit/Desktop/CRUD/env/lib/python3.6/site-packages/django/views/generic/base.py", line 71, in view
    return self.dispatch(request, *args, **kwargs)
  File "/home/rohit/Desktop/CRUD/env/lib/python3.6/site-packages/rest_framework/views.py", line 505, in dispatch
    response = self.handle_exception(exc)
  File "/home/rohit/Desktop/CRUD/env/lib/python3.6/site-packages/rest_framework/views.py", line 465, in handle_exception
    self.raise_uncaught_exception(exc)
  File "/home/rohit/Desktop/CRUD/env/lib/python3.6/site-packages/rest_framework/views.py", line 476, in raise_uncaught_exception
    raise exc
  File "/home/rohit/Desktop/CRUD/env/lib/python3.6/site-packages/rest_framework/views.py", line 502, in dispatch
    response = handler(request, *args, **kwargs)
  File "/home/rohit/Desktop/CRUD/env/lib/python3.6/site-packages/rest_framework/decorators.py", line 50, in handler
    return func(*args, **kwargs)
  File "/home/rohit/Desktop/CRUD/POLITICS/district/views.py", line 477, in one_to_many
    q2 = Language.objects.order_by('id')[-2].id
  File "/home/rohit/Desktop/CRUD/env/lib/python3.6/site-packages/django/db/models/query.py", line 293, in __getitem__
    "Negative indexing is not supported."
AssertionError: Negative indexing is not supported.
2021-01-29 19:35:41,394 [ERROR] {/home/rohit/Desktop/CRUD/env/lib/python3.6/site-packages/django/utils/log.py:228} : Internal Server Error: /district/oneToMany
Traceback (most recent call last):
  File "/home/rohit/Desktop/CRUD/env/lib/python3.6/site-packages/django/core/handlers/exception.py", line 34, in inner
    response = get_response(request)
  File "/home/rohit/Desktop/CRUD/env/lib/python3.6/site-packages/django/core/handlers/base.py", line 115, in _get_response
    response = self.process_exception_by_middleware(e, request)
  File "/home/rohit/Desktop/CRUD/env/lib/python3.6/site-packages/django/core/handlers/base.py", line 113, in _get_response
    response = wrapped_callback(request, *callback_args, **callback_kwargs)
  File "/home/rohit/Desktop/CRUD/env/lib/python3.6/site-packages/django/views/decorators/csrf.py", line 54, in wrapped_view
    return view_func(*args, **kwargs)
  File "/home/rohit/Desktop/CRUD/env/lib/python3.6/site-packages/django/views/generic/base.py", line 71, in view
    return self.dispatch(request, *args, **kwargs)
  File "/home/rohit/Desktop/CRUD/env/lib/python3.6/site-packages/rest_framework/views.py", line 505, in dispatch
    response = self.handle_exception(exc)
  File "/home/rohit/Desktop/CRUD/env/lib/python3.6/site-packages/rest_framework/views.py", line 465, in handle_exception
    self.raise_uncaught_exception(exc)
  File "/home/rohit/Desktop/CRUD/env/lib/python3.6/site-packages/rest_framework/views.py", line 476, in raise_uncaught_exception
    raise exc
  File "/home/rohit/Desktop/CRUD/env/lib/python3.6/site-packages/rest_framework/views.py", line 502, in dispatch
    response = handler(request, *args, **kwargs)
  File "/home/rohit/Desktop/CRUD/env/lib/python3.6/site-packages/rest_framework/decorators.py", line 50, in handler
    return func(*args, **kwargs)
  File "/home/rohit/Desktop/CRUD/POLITICS/district/views.py", line 477, in one_to_many
    q2 = Language.objects.order_by('id')[:3].last()
  File "/home/rohit/Desktop/CRUD/env/lib/python3.6/site-packages/django/db/models/query.py", line 669, in last
    for obj in (self.reverse() if self.ordered else self.order_by('-pk'))[:1]:
  File "/home/rohit/Desktop/CRUD/env/lib/python3.6/site-packages/django/db/models/query.py", line 1115, in reverse
    raise TypeError('Cannot reverse a query once a slice has been taken.')
TypeError: Cannot reverse a query once a slice has been taken.
2021-01-29 19:36:04,942 [ERROR] {/home/rohit/Desktop/CRUD/env/lib/python3.6/site-packages/django/utils/log.py:228} : Internal Server Error: /district/oneToMany
Traceback (most recent call last):
  File "/home/rohit/Desktop/CRUD/env/lib/python3.6/site-packages/django/core/handlers/exception.py", line 34, in inner
    response = get_response(request)
  File "/home/rohit/Desktop/CRUD/env/lib/python3.6/site-packages/django/core/handlers/base.py", line 115, in _get_response
    response = self.process_exception_by_middleware(e, request)
  File "/home/rohit/Desktop/CRUD/env/lib/python3.6/site-packages/django/core/handlers/base.py", line 113, in _get_response
    response = wrapped_callback(request, *callback_args, **callback_kwargs)
  File "/home/rohit/Desktop/CRUD/env/lib/python3.6/site-packages/django/views/decorators/csrf.py", line 54, in wrapped_view
    return view_func(*args, **kwargs)
  File "/home/rohit/Desktop/CRUD/env/lib/python3.6/site-packages/django/views/generic/base.py", line 71, in view
    return self.dispatch(request, *args, **kwargs)
  File "/home/rohit/Desktop/CRUD/env/lib/python3.6/site-packages/rest_framework/views.py", line 505, in dispatch
    response = self.handle_exception(exc)
  File "/home/rohit/Desktop/CRUD/env/lib/python3.6/site-packages/rest_framework/views.py", line 465, in handle_exception
    self.raise_uncaught_exception(exc)
  File "/home/rohit/Desktop/CRUD/env/lib/python3.6/site-packages/rest_framework/views.py", line 476, in raise_uncaught_exception
    raise exc
  File "/home/rohit/Desktop/CRUD/env/lib/python3.6/site-packages/rest_framework/views.py", line 502, in dispatch
    response = handler(request, *args, **kwargs)
  File "/home/rohit/Desktop/CRUD/env/lib/python3.6/site-packages/rest_framework/decorators.py", line 50, in handler
    return func(*args, **kwargs)
  File "/home/rohit/Desktop/CRUD/POLITICS/district/views.py", line 477, in one_to_many
    q2 = Language.objects.order_by('-id')[:3].last()
  File "/home/rohit/Desktop/CRUD/env/lib/python3.6/site-packages/django/db/models/query.py", line 669, in last
    for obj in (self.reverse() if self.ordered else self.order_by('-pk'))[:1]:
  File "/home/rohit/Desktop/CRUD/env/lib/python3.6/site-packages/django/db/models/query.py", line 1115, in reverse
    raise TypeError('Cannot reverse a query once a slice has been taken.')
TypeError: Cannot reverse a query once a slice has been taken.
